Workbook
Name BB: #REF!
Name CCC: #REF!
Name div: 'BD jeans Dama'!#REF!
Name his: #REF!
Name hist: #REF!
Name JEAN: 'BD jeans Dama'!#REF!
Name jeandama: 'BD jeans Dama'!#REF!
Name jeans: 'BD jeans Dama'!$A$1:$E$1404
Name jeanss: 'BD jeans Dama'!#REF!
Name jeansss: 'BD jeans Dama'!$A$1:$E$4044
Name jn: 'BD jeans Dama'!#REF!
Name jnss: 'BD jeans Dama'!$A$2:$E$518
Name L: 'BASE DE DATOS OFICIAL'!$A$1:$D$126
Name mahis: #REF!
Name matof: 'BASE DE DATOS OFICIAL'!$A$16:$AF$371
Name matrix: #REF!
Name matrizoficial: 'BASE DE DATOS OFICIAL'!$16:$65452
Name MAX: #REF!
Name MAXX: #REF!
Name PLANILLA: #REF!
Name PLANILLA1: 'BASE DE DATOS OFICIAL'!$A$3:$CU$373
Name PLANILLA2: #REF!
Name PLANILLAMOD: 'BASE DE DATOS OFICIAL'!$A$16:$V$122
Name RUT: #REF!
Name RUTES: #REF!
Name VENTAS: #REF!

Sheet TOMA DE PEDIDOS
D1: TRANSPORTE | G1: RAZON SOCIAL | K1: =_xlfn.IFNA(VLOOKUP(K5,'BASE DE DATOS OFICIAL'!$A$4:$AC$166,3,0),"SIN INFORMACIÓN") -> ESTABLECIMIENTOS GERMANI S.A.
G2: GIRO | K2: =_xlfn.IFNA(VLOOKUP(K5,'BASE DE DATOS OFICIAL'!$A$4:$AC$166,19,0),"SIN INFORMACIÓN") -> GRANDES TIENDAS
D3: =VLOOKUP(K5,'BASE DE DATOS OFICIAL'!A3:AC166,14,0) -> LOGISTEX | G3: DIRECCION | K3: =_xlfn.IFNA(VLOOKUP(K5,'BASE DE DATOS OFICIAL'!$A$4:$AC$166,5,0),"SIN INFORMACIÓN") -> 1 SUR 1442
G4: NOMBRE TIENDA | K4: =_xlfn.IFNA(VLOOKUP(K5,'BASE DE DATOS OFICIAL'!$A$4:$AC$166,20,0),"SIN INFORMACIÓN") -> GERMANI
D5: CONDICIONES DE PAGO | G5: RUT | K5: 89.258.600-4 | P5: FECHA
G6: COMUNA | K6: =_xlfn.IFNA(VLOOKUP(K5,'BASE DE DATOS OFICIAL'!$A$4:$AC$166,21,0),"SIN INFORMACIÓN") -> TALCA | P6: CIUDAD | R6: =_xlfn.IFNA(VLOOKUP(K5,'BASE DE DATOS OFICIAL'!$A$4:$AC$166,4,0),"SIN INFORMACIÓN") -> TALCA
A7: MANUFACTURAS e IMPORTACIONES | D7: =_xlfn.IFNA(VLOOKUP(K5,'BASE DE DATOS OFICIAL'!$A$4:$AC$166,17,0),"SIN INFORMACIÓN") -> CONTADO -30DIAS | G7: TELEFONO | K7: =_xlfn.IFNA(VLOOKUP(K5,'BASE DE DATOS OFICIAL'!$A$4:$AC$166,6,0),"SIN INFORMACIÓN") -> 71-2229001 | P7: CELULAR | R7: =_xlfn.IFNA(VLOOKUP(K5,'BASE DE DATOS OFICIAL'!$A$4:$AC$166,18,0),"SIN INFORMACIÓN") -> 0
A8: TITANIUM CHILE SPA | G8: ATENCION | K8: =TODAY() -> 46094 | P8: E-MAIL | R8: =_xlfn.IFNA(VLOOKUP(K5,'BASE DE DATOS OFICIAL'!$A$4:$AC$166,9,0),"SIN INFORMACIÓN") -> 0
D9: NOTA DE PEDIDO | G9: VENDEDOR | K9: =_xlfn.IFNA(VLOOKUP(K5,'BASE DE DATOS OFICIAL'!$A$4:$AC$166,7,0),"SIN INFORMACIÓN") -> RICHARD CUEVAS | P9: ORDEN DE COMPRA | R9: 42 OTOÑO INVIERNO
A10: Av. Peru 710, Recoleta-Santiago | G10: TEMPORADA | K10: OTOÑO INVIERNO 2026
A11: www.mohicano.cl | D11: 142813 | G11: VENTA SUGERIDA | K11: =_xlfn.IFNA(VLOOKUP(K5,'BASE DE DATOS OFICIAL'!$A$4:$AC$166,29,0),"SIN INFORMACIÓN") -> 493.35 | M11: prendas | P11: DESCUENTO
G12: COLE. ANTERIOR | K12: PEDIDO REALIZADO | P12: DESPACHO | R12: SALDO | S12: VALOR
G13: 3800 | K13: =_xlfn.IFNA(VLOOKUP(K5,'BASE DE DATOS OFICIAL'!$A$4:$AC$166,24,0),"SIN INFORMACIÓN") -> 481 | P13: =_xlfn.IFNA(VLOOKUP(K5,'BASE DE DATOS OFICIAL'!$A$4:$AC$166,25,0),"SIN INFORMACIÓN") -> 454 | R13: =_xlfn.IFNA(VLOOKUP(K5,'BASE DE DATOS OFICIAL'!$A$4:$AC$166,26,0),"SIN INFORMACIÓN") -> 27 | S13: =_xlfn.IFNA(VLOOKUP(K5,'BASE DE DATOS OFICIAL'!$A$4:$AC$166,28,0),"SIN INFORMACIÓN") -> 11679460
A14: COD | B14: ARTÍCULO | C14: TIRO | D14: CORTE | E14: 36 | F14: 38 | G14: 40 | H14: 42 | I14: 44 | J14: 46 | K14: 48 | L14: 50 | M14: S | N14: M | O14: L | P14: PRENDAS | R14: VALOR | S14: TOTAL
A15: 4221-01 | B15: =IF(A15="","",VLOOKUP(A15,jeans,2,FALSE)) -> BIO MEDIO FOCALIZADOPRETINA CRUZADA 3 PINZA TRASERO | C15: =IF(A15="","",VLOOKUP(A15,jeans,3,FALSE)) -> CINTURA | D15: =IF(A15="","",VLOOKUP(A15,jeans,4,FALSE)) -> TOBILLERO | P15: =SUM($E15:$O15) -> 0 | R15: =IF(A15="","",VLOOKUP(A15,jeans,5,FALSE)) -> 24990 | S15: =IFERROR(P15*R15,"") -> 0
A16: 4226 | B16: =IF(A16="","",VLOOKUP(A16,jeans,2,FALSE)) -> BLUE BLACK FOCALIZADO 2 RELOJERO ANCHO BOLS TRASERO PINZA+CORTE ALTURA 3 PINZAS | C16: =IF(A16="","",VLOOKUP(A16,jeans,3,FALSE)) -> MEDIO | D16: =IF(A16="","",VLOOKUP(A16,jeans,4,FALSE)) -> PITILLO | P16: =SUM($E16:$O16) -> 0 | R16: =IF(A16="","",VLOOKUP(A16,jeans,5,FALSE)) -> 24990 | S16: =IFERROR(P16*R16,"") -> 0
A17: 4246-00 | B17: =IF(A17="","",VLOOKUP(A17,jeans,2,FALSE)) -> MEDIO FOCALIZADO CORTE DELANTERO PESPUNTE 2 PINZA TRASERO | C17: =IF(A17="","",VLOOKUP(A17,jeans,3,FALSE)) -> CINTURA | D17: =IF(A17="","",VLOOKUP(A17,jeans,4,FALSE)) -> TOBILLERO | P17: =SUM($E17:$O17) -> 0 | R17: =IF(A17="","",VLOOKUP(A17,jeans,5,FALSE)) -> 24990 | S17: =IFERROR(P17*R17,"") -> 0
A18: 4201-01 | B18: =IF(A18="","",VLOOKUP(A18,jeans,2,FALSE)) -> BIOOSCURO FOCALIZADO 2 RELOJ ANCHO BOLS TRASERO CORTE 3 PINZA TRASERO | C18: =IF(A18="","",VLOOKUP(A18,jeans,3,FALSE)) -> CINTURA | D18: =IF(A18="","",VLOOKUP(A18,jeans,4,FALSE)) -> PITILLO | P18: =SUM($E18:$O18) -> 0 | R18: =IF(A18="","",VLOOKUP(A18,jeans,5,FALSE)) -> 24990 | S18: =IFERROR(P18*R18,"") -> 0
A19: 4235-01 | B19: =IF(A19="","",VLOOKUP(A19,jeans,2,FALSE)) -> idem 4226-01 laser 2 CIERRES EN VISTA DELANTERO 3 PINZA TRASERO DREMEL BOLSILLOS | C19: =IF(A19="","",VLOOKUP(A19,jeans,3,FALSE)) -> CINTURA | D19: =IF(A19="","",VLOOKUP(A19,jeans,4,FALSE)) -> PITILLO | P19: =SUM($E19:$O19) -> 0 | R19: =IF(A19="","",VLOOKUP(A19,jeans,5,FALSE)) -> 24990 | S19: =IFERROR(P19*R19,"") -> 0
A20: 4227-00 | B20: =IF(A20="","",VLOOKUP(A20,jeans,2,FALSE)) -> AZUL INDUSTRIAL DOBLE RELOJERO 2 TONOS DE HILOS | C20: =IF(A20="","",VLOOKUP(A20,jeans,3,FALSE)) -> CINTURA | D20: =IF(A20="","",VLOOKUP(A20,jeans,4,FALSE)) -> RECTO TOBI | P20: =SUM($E20:$O20) -> 0 | R20: =IF(A20="","",VLOOKUP(A20,jeans,5,FALSE)) -> 24990 | S20: =IFERROR(P20*R20,"") -> 0
A21: 4222-00 | B21: =IF(A21="","",VLOOKUP(A21,jeans,2,FALSE)) -> BIOMEDIO FOCALIZADO LASER PASADOR BOLS TRAS/DELANTERO 3 COSTURA ALTURA | C21: =IF(A21="","",VLOOKUP(A21,jeans,3,FALSE)) -> CADERA | D21: =IF(A21="","",VLOOKUP(A21,jeans,4,FALSE)) -> PITILLO | P21: =SUM($E21:$O21) -> 0 | R21: =IF(A21="","",VLOOKUP(A21,jeans,5,FALSE)) -> 24990 | S21: =IFERROR(P21*R21,"") -> 0
A22: 4201-00 | B22: =IF(A22="","",VLOOKUP(A22,jeans,2,FALSE)) -> BLUE BLACK FOCALIZADO SIN TACHAS | C22: =IF(A22="","",VLOOKUP(A22,jeans,3,FALSE)) -> CINTURA | D22: =IF(A22="","",VLOOKUP(A22,jeans,4,FALSE)) -> PITILLO | P22: =SUM($E22:$O22) -> 0 | R22: =IF(A22="","",VLOOKUP(A22,jeans,5,FALSE)) -> 24990 | S22: =IFERROR(P22*R22,"") -> 0
A23: 4206-00 | B23: =IF(A23="","",VLOOKUP(A23,jeans,2,FALSE)) -> NEGRO1 RELOJERO APLICACIÓN ECO CUERO PRETINA 3PINZA TRASERO | C23: =IF(A23="","",VLOOKUP(A23,jeans,3,FALSE)) -> CINTURA | D23: =IF(A23="","",VLOOKUP(A23,jeans,4,FALSE)) -> PITILLO | P23: =SUM($E23:$O23) -> 0 | R23: =IF(A23="","",VLOOKUP(A23,jeans,5,FALSE)) -> 24990 | S23: =IFERROR(P23*R23,"") -> 0
A24: 4248-00 | B24: =IF(A24="","",VLOOKUP(A24,jeans,2,FALSE)) -> NEGRO 2 PINZA TRASERO BOLSILLOS CUADRADOS TRAS | C24: =IF(A24="","",VLOOKUP(A24,jeans,3,FALSE)) -> CINTURA | D24: =IF(A24="","",VLOOKUP(A24,jeans,4,FALSE)) -> RECTO | P24: =SUM($E24:$O24) -> 0 | R24: =IF(A24="","",VLOOKUP(A24,jeans,5,FALSE)) -> 25990 | S24: =IFERROR(P24*R24,"") -> 0
A25: 4248-01 | B25: =IF(A25="","",VLOOKUP(A25,jeans,2,FALSE)) -> GRIS FOCALIZADO 2 PINZA TRASERO | C25: =IF(A25="","",VLOOKUP(A25,jeans,3,FALSE)) -> CINTURA | D25: =IF(A25="","",VLOOKUP(A25,jeans,4,FALSE)) -> RECTO | P25: =SUM($E25:$O25) -> 0 | R25: =IF(A25="","",VLOOKUP(A25,jeans,5,FALSE)) -> 25990 | S25: =IFERROR(P25*R25,"") -> 0
A26: 4227-01 | B26: =IF(A26="","",VLOOKUP(A26,jeans,2,FALSE)) -> BIOMEDIO FOCALIZADODOBLE RELOJERO 2 TONOS DE HILOS | C26: =IF(A26="","",VLOOKUP(A26,jeans,3,FALSE)) -> CINTURA | D26: =IF(A26="","",VLOOKUP(A26,jeans,4,FALSE)) -> RECTO TOBI | P26: =SUM($E26:$O26) -> 0 | R26: =IF(A26="","",VLOOKUP(A26,jeans,5,FALSE)) -> 24990 | S26: =IFERROR(P26*R26,"") -> 0
A27: 4202-00 | B27: =IF(A27="","",VLOOKUP(A27,jeans,2,FALSE)) -> BIO OSCURO FOCALIZADO2 RELOJ ANCHO 3 COSTURA ALTURA | C27: =IF(A27="","",VLOOKUP(A27,jeans,3,FALSE)) -> CINTURA | D27: =IF(A27="","",VLOOKUP(A27,jeans,4,FALSE)) -> RECTO | P27: =SUM($E27:$O27) -> 0 | R27: =IF(A27="","",VLOOKUP(A27,jeans,5,FALSE)) -> 25990 | S27: =IFERROR(P27*R27,"") -> 0
A28: 4247-00 | B28: =IF(A28="","",VLOOKUP(A28,jeans,2,FALSE)) -> BIO MEDIO FOCALIZADO BOLSILLOS TRASERO OVALADOS | C28: =IF(A28="","",VLOOKUP(A28,jeans,3,FALSE)) -> CINTURA | D28: =IF(A28="","",VLOOKUP(A28,jeans,4,FALSE)) -> RECTO | P28: =SUM($E28:$O28) -> 0 | R28: =IF(A28="","",VLOOKUP(A28,jeans,5,FALSE)) -> 25990 | S28: =IFERROR(P28*R28,"") -> 0
... A34: 4214-60 | B34: =IF(A34="","",VLOOKUP(A34,jeans,2,FALSE)) -> MARENGO FOCALIZADOCORTE DELANTERO 3 PINZAS TRASERAS TACHAS PRETINA | C34: =IF(A34="","",VLOOKUP(A34,jeans,3,FALSE)) -> CINTURA | D34: =IF(A34="","",VLOOKUP(A34,jeans,4,FALSE)) -> OXFORD | P34: =SUM($E34:$O34) -> 0 | R34: =IF(A34="","",VLOOKUP(A34,jeans,5,FALSE)) -> 27990 | S34: =IFERROR(P34*R34,"") -> 0
B35: =IF(A35="","",VLOOKUP(A35,jeans,2,FALSE)) | C35: =IF(A35="","",VLOOKUP(A35,jeans,3,FALSE)) | D35: =IF(A35="","",VLOOKUP(A35,jeans,4,FALSE)) | P35: =SUM($E35:$O35) -> 0 | R35: =IF(A35="","",VLOOKUP(A35,jeans,5,FALSE)) | S35: =IFERROR(P35*R35,"")
B36: =IF(A36="","",VLOOKUP(A36,jeans,2,FALSE)) | C36: =IF(A36="","",VLOOKUP(A36,jeans,3,FALSE)) | D36: =IF(A36="","",VLOOKUP(A36,jeans,4,FALSE)) | P36: =SUM($E36:$O36) -> 0 | R36: =IF(A36="","",VLOOKUP(A36,jeans,5,FALSE)) | S36: =IFERROR(P36*R36,"")
B37: =IF(A37="","",VLOOKUP(A37,jeans,2,FALSE)) | C37: =IF(A37="","",VLOOKUP(A37,jeans,3,FALSE)) | D37: =IF(A37="","",VLOOKUP(A37,jeans,4,FALSE)) | P37: =SUM($E37:$O37) -> 0 | R37: =IF(A37="","",VLOOKUP(A37,jeans,5,FALSE)) | S37: =IFERROR(P37*R37,"")
B38: =IF(A38="","",VLOOKUP(A38,jeans,2,FALSE)) | C38: =IF(A38="","",VLOOKUP(A38,jeans,3,FALSE)) | D38: =IF(A38="","",VLOOKUP(A38,jeans,4,FALSE)) | P38: =SUM($E38:$O38) -> 0 | R38: =IF(A38="","",VLOOKUP(A38,jeans,5,FALSE)) | S38: =IFERROR(P38*R38,"")
B39: =IF(A39="","",VLOOKUP(A39,jeans,2,FALSE)) | C39: =IF(A39="","",VLOOKUP(A39,jeans,3,FALSE)) | D39: =IF(A39="","",VLOOKUP(A39,jeans,4,FALSE)) | P39: =SUM($E39:$O39) -> 0 | R39: =IF(A39="","",VLOOKUP(A39,jeans,5,FALSE)) | S39: =IFERROR(P39*R39,"")
B40: =IF(A40="","",VLOOKUP(A40,jeans,2,FALSE)) | C40: =IF(A40="","",VLOOKUP(A40,jeans,3,FALSE)) | D40: =IF(A40="","",VLOOKUP(A40,jeans,4,FALSE)) | P40: =SUM($E40:$O40) -> 0 | R40: =IF(A40="","",VLOOKUP(A40,jeans,5,FALSE)) | S40: =IFERROR(P40*R40,"")
B41: =IF(A41="","",VLOOKUP(A41,jeans,2,FALSE)) | C41: =IF(A41="","",VLOOKUP(A41,jeans,3,FALSE)) | D41: =IF(A41="","",VLOOKUP(A41,jeans,4,FALSE)) | P41: =SUM($E41:$O41) -> 0 | R41: =IF(A41="","",VLOOKUP(A41,jeans,5,FALSE)) | S41: =IFERROR(P41*R41,"")
B42: =IF(A42="","",VLOOKUP(A42,jeans,2,FALSE)) | C42: =IF(A42="","",VLOOKUP(A42,jeans,3,FALSE)) | D42: =IF(A42="","",VLOOKUP(A42,jeans,4,FALSE)) | P42: =SUM($E42:$O42) -> 0 | R42: =IF(A42="","",VLOOKUP(A42,jeans,5,FALSE)) | S42: =IFERROR(P42*R42,"")
B43: =IF(A43="","",VLOOKUP(A43,jeans,2,FALSE)) | C43: =IF(A43="","",VLOOKUP(A43,jeans,3,FALSE)) | D43: =IF(A43="","",VLOOKUP(A43,jeans,4,FALSE)) | P43: =SUM($E43:$O43) -> 0 | R43: =IF(A43="","",VLOOKUP(A43,jeans,5,FALSE)) | S43: =IFERROR(P43*R43,"")
B44: =IF(A44="","",VLOOKUP(A44,jeans,2,FALSE)) | C44: =IF(A44="","",VLOOKUP(A44,jeans,3,FALSE)) | D44: =IF(A44="","",VLOOKUP(A44,jeans,4,FALSE)) | P44: =SUM($E44:$O44) -> 0 | R44: =IF(A44="","",VLOOKUP(A44,jeans,5,FALSE)) | S44: =IFERROR(P44*R44,"")
B45: =IF(A45="","",VLOOKUP(A45,jeans,2,FALSE)) | C45: =IF(A45="","",VLOOKUP(A45,jeans,3,FALSE)) | D45: =IF(A45="","",VLOOKUP(A45,jeans,4,FALSE)) | P45: =SUM($E45:$O45) -> 0 | R45: =IF(A45="","",VLOOKUP(A45,jeans,5,FALSE)) | S45: =IFERROR(P45*R45,"")
...

Sheet Hoja2

Sheet Hoja1

Sheet BD jeans Dama
A1: ARTICULO | B1: DESCRIPCIÓN | C1: TIRO | D1: BOTA | E1: PRECIO
A2: 3801 | B2: Pretina revés, doble bolsillo relojero, cierre bota | C2: Cintura | D2: Tobillero | E2: 24990
A3: 3802 | B3: Smart Denim pinza costado sin basta | C3: Cintura | D3: Oxford | E3: 25990
A4: 3818 | B4: Marengo con roturas láser | C4: Cintura | D4: Recto | E4: 24990
A5: 3821-00 | B5: Imprentado biodesgastado | C5: Medio | D5: Oxford | E5: 24990
A6: 3821-01 | B6: Bolsillo delantero, costura ancha, Imprentado ox. | C6: Medio | D6: Oxford | E6: 24990
A7: 3826 | B7: Vestido negro con cinturón | C7: Vestido | D7: Muslo | E7: 28990
A8: 3832-09 | B8: Verde con pretina desflecada | C8: Cintura | D8: Palazzo | E8: 26990
A9: 3834 | B9: Clásico 5 bolsillos, gris con repaso costura | C9: Cintura | D9: Palazzo | E9: 26990
A10: 3837 | B10: Cargo negro Eco Cuero | C10: Cintura | D10: Recto | E10: 26990
A11: 3840 | B11: Clásico gris gravillado, bolsillos traseros curvos | C11: Cintura | D11: Flare | E11: 25990
A12: 3846-04 | B12: Cargo 4 bolsillos color chocolate | C12: Medio | D12: Palazzo | E12: 26990
A13: 3846-06 | B13: Cargo 4 bolsillos teñido orgánico con nueces | C13: Medio | D13: Palazzo | E13: 26990
A14: 3846-09 | B14: Cargo 4 bolsillos color Verde Oliva | C14: Medio | D14: Palazzo | E14: 26990
A15: 3846-38 | B15: Cargo 4 bolsillos color Ostra | C15: Medio | D15: Palazzo | E15: 26990
A16: 3846-71 | B16: Cargo 4 bolsillos color Terracota | C16: Medio | D16: Palazzo | E16: 26990
A17: 3849 | B17: Clásico | C17: Cintura | D17: Pitillo | E17: 24990
A18: 3853-04 | B18: Cargo/cinturón chocolate hilo al tono | C18: Cintura | D18: Oxford | E18: 26990
A19: 3851 | B19: Pieza lateral | C19: Cintura | D19: Palazzo | E19: 26990
A20: 3857 | B20: Azúl focalizado tenue, pinzas delanteras y traseras | C20: Cintura | D20: Pitillo | E20: 24990
A21: 3858 | B21: Wide Leg marengo | C21: Cintura | D21: Recto/ Cargo | E21: 26990
A22: 3859 | B22: Casaca oversize, bordado, gravillado | C22: Casaca | E22: 25990
A23: 3860 | B23: Corte diagonal en pretina | C23: Medio | D23: Tobillero | E23: 24990
A24: 3861 | B24: HIGH WAIST sin pinza | C24: Cintura | D24: Recto | E24: 24990
A25: 3862-00 | B25: Clásico color negro bolsillos traseros ovalados | C25: Medio | D25: Recto | E25: 24990
A26: 3862-01 | B26: Clásico Gris focalizado bolsillos traseros ovalados | C26: Medio | D26: Recto | E26: 24990
A27: 3865 | B27: Push in push up azúl focalizado | C27: Cintura | D27: Flare | E27: 25990
A28: 3869 | B28: Negro pestaña bolsillo delantero | C28: Cintura | D28: Flare | E28: 25990
A29: 3870 | B29: Casaca oversize con tapetas, gravillado | C29: Casaca | E29: 26990
A30: 3871-00 | B30: Pretina ancha con doble botón Bio Medio | C30: Cintura | D30: Pitillo | E30: 24990
A31: 3871-01 | B31: Pretina ancha c/doble botón, focalizado oxidado | C31: Cintura | D31: Pitillo | E31: 24990
A32: 3877 | B32: Negro con aplicación Lumen | C32: Cintura | D32: Pitillo | E32: 24990
A33: 3878 | B33: Pretina desflecada sin basta desflecada | C33: Cintura | D33: Palazzo | E33: 26990
A34: 3879 | B34: Tajali en bota, pieza en altura bigotes | C34: Medio | D34: Tobillero | E34: 24990
A35: 3880 | B35: Smart Denim roturas delanteras | C35: Cintura | D35: Tobillero | E35: 24990
A36: 3882-00 | B36: Marengo gravillado 2 pasadores, pinza lateral | C36: Cintura | D36: Recto | E36: 24990
A37: 3882-01 | B37: Negro 2 pasadores, pinza lateral | C37: Cintura | D37: Recto | E37: 24990
A38: 3883 | B38: Clásico 5 bolsillos bolsillo trasero destroyed | C38: Cintura | D38: Recto | E38: 24990
A39: 3886 | B39: Wide Leg azúl focalizado tenue | C39: Cintura | D39: Palazzo | E39: 26990
A40: 3888 | B40: Cargo azúl, con bolsillos carpinteros | C40: Cintura | D40: Recto | E40: 26990
...

Sheet Respaldo
A1: 1 | B1: 1 | C1: 2 | D1: 3 | E1: 4 | F1: 5 | G1: 6 | H1: 7 | I1: 8 | J1: 9 | K1: 10 | L1: 11 | M1: 12 | N1: 13 | O1: 14 | P1: 15 | Q1: 16 | R1: 17 | S1: 18 | T1: 19 | U1: 20 | V1: 21 | W1: 22 | X1: 23 | Y1: 24 | Z1: 25 | AA1: 26 | AB1: 27 | AC1: 28
A3: RUT | B3: RUT2 | C3: Razon Social | D3: Ciudad | E3: Direccion | F3: Fono | G3: Vendedor | H3: Correo | I3: WWW | J3: Contacto | K3: Cargo | L3: GRUPO | M3: Credito | N3: Transporte | O3: BLOQUEADO | P3: Dcto | Q3: CONDICION DE PAGO | R3: CELULAR | S3: GIRO | T3: NOMBRE DE TIENDA | U3: COMUNA | V3: Observaciones | W3: Ped_anterior | X3: Cantidad | Y3: Despacho | Z3: Saldo | AA3: % Despacho | AB3: Valor | AC3: Meta Cole-38
A4: 4.878.758-4 | B4: 48787584 | C4: ROBERTO KOBUS PEMSO | D4: ANCUD | E4: PUDETO 143-145 | F4: 998269854 | G4: PATRICIO CUEVAS | H4: tiendasmachos@gmail.com | I4: MACHOS BOUTIQUE@SURNET.CL | J4: JENIFER PAGOS | L4: 4 | M4: 0 | N4: VARMONTT | Q4: CREDITO 30 Y 60 | S4: GRANDES TIENDAS | T4: MACHOS | U4: ANCUD | V4: VARMONTT | X4: 487 | Y4: 432 | Z4: 55 | AA4: 0.88706366 | AB4: 12047130 | AC4: 782
A5: 5.001.562-9 | B5: 50015629 | C5: INES VARGAS PINO | D5: COPIAPO | E5: ATACAMA 461-A | F5: 52-213939 | G5: HECTOR CAFFIERO | J5: INES VARGAS | L5: 3 | M5: 0 | N5: SER VALL | P5: 0.05 | Q5: TRANSF. CONTRA FACTURA | R5: 8-8637797 | S5: TIENDA DE VESTIR | T5: BOUTIQUE GEMINIS | U5: COPIAPO | X5: 0 | Y5: 0 | Z5: 0 | AA5: 0 | AB5: 0 | AC5: 0
A6: 5.384.900-8 | B6: 53849008 | C6: ELIANA RIQUELME R. | D6: FUTRONO | E6: BALMACEDA 249 | F6: 966322618 | G6: PATRICIO CUEVAS | J6: ELIANA RIQUELME | L6: 4 | M6: 0 | N6: TUR BUS | Q6: CREDITO 30 Y 60 | S6: VENTAS | T6: COSAS BOUTIQUE | U6: FUTRONO | X6: 0 | Y6: 0 | Z6: 0 | AA6: 0 | AB6: 0 | AC6: 0
A7: 5.913.365-9 | B7: 59133659 | C7: ANA MARIA MANFREDI CARRASCO | D7: OVALLE | E7: VICUÑA MACKENNA 287 | F7: 053-622626 | G7: HECTOR CAFFIERO | H7: manfredi@hotmail.com | J7: DANIELA O ANA MARIA | K7: DUEÑO | L7: 3 | M7: 0 | N7: CHILE LINDO | Q7: CREDITO 30 Y 60 | S7: VENTAS AL POR MENOR | T7: BOUTIQUE PARA TI | U7: =D7 -> OVALLE | X7: 182 | Y7: 116 | Z7: 66 | AA7: 0.63736264 | AB7: 4477180 | AC7: 186.3
A8: 6.031.123-4 | B8: 60311234 | C8: FABIOLA BENAVENTE MEZA | D8: PARRAL | E8: ANIBAL PINTO 590 | F8: 961895384 | G8: CARLOS CUEVAS | H8: tiendaelegance@gmail.com | J8: FABIOLA BENAVENTE | K8: POP DESPACHADO 11/12 | L8: 3 | M8: 0 | N8: VILLA PRAT | Q8: CONTRAFACTURA | S8: BOUTIQUE | T8: ELEGANTE BOUTIQUE | U8: PARRAL | X8: 90 | Y8: 88 | Z8: 2 | AA8: 0.97777778 | AB8: 2223100 | AC8: 51.75
A9: 6.331.910-4 | B9: 63319104 | C9: LUIS SOUMASTRE RAMIREZ | D9: ARICA | E9: 21 DE MAYO 454 | F9: 058-2232959 | G9: HECTOR CAFFIERO | H9: lfsr24@hotmail.com | J9: gloria tapia | L9: 3 | M9: 0 | N9: CHACON | Q9: CREDITO 30 Y 60 | S9: VENTAS AL POR MENOR | U9: ARICA | X9: 0 | Y9: 0 | Z9: 0 | AA9: 0 | AB9: 0 | AC9: 26.45
A10: 6.589.904-3 | B10: 65899043 | C10: ANITA BERTA GADICKE | D10: OSORNO | E10: OHIGGINS 534 | F10: 985067217 | G10: PATRICIO CUEVAS | H10: anitagadicke@gmail.com | J10: ANITA GADICKE | L10: 4 | M10: 0 | N10: CIDHER | Q10: CREDITO 30 Y 60 | S10: BOUTIQUE | T10: ALBANY SPORT | U10: OSORNO | X10: 0 | Y10: 0 | Z10: 0 | AA10: 0 | AB10: 0 | AC10: 0
A11: 6.775.324-0 | B11: 67753240 | C11: MARIA DE LOS ANGELES DIAZ BELLIDO | D11: VILLA ALEMANA | E11: BUENOS AIRE 845 | F11: 32-2951011 | G11: PATRICIO CUEVAS | H11: balaustros2@hotmail.com | I11: BALASUTROSVILLAALEMANA@GMAIL.C | J11: MARIA DE LOS ANGELES | L11: 4 | N11: ABC | Q11: CREDITO 30 Y 60 | S11: BOUTIQUE | T11: BALAUSTROS BOUTIQUE | U11: VILLA ALEMANA | X11: 0 | Y11: 0 | Z11: 0 | AA11: 0 | AB11: 0 | AC11: 0
A12: 6.799.967-3 | B12: 67999673 | C12: ANA MARIA SALVATIERRA TAPIA | D12: CABILDO | E12: HUMERES 727 | F12: 91286053 | G12: CARLOS CUEVAS | H12: anisalta@hotmail.com | J12: ANA MARIA SALVATIERR | L12: 3 | M12: 0 | N12: TUR BUS | Q12: CREDITO 30 Y 60 | S12: BOUTIQUE | T12: BOUTIQUE ANITA | U12: CABILDO | X12: 180 | Y12: 176 | Z12: 4 | AA12: 0.97777778 | AB12: 4426200 | AC12: 216.2
A13: 76.965.431-3 | B13: 769654313 | C13: OPALO VESTUARIO | D13: CONCEPCION | E13: BARROS ARANA 815 LOCAL 14 | F13: 991959818 | G13: PATRICIO CUEVAS | H13: mayobenites@hotmail.com | J13: HILIA CONCHA | K13: DUEÑA | L13: 1 | M13: 0 | N13: CHEVALIER | Q13: CHEQUE 30 DIAS | R13: 99594046 | S13: BOUTIQUE | T13: OPALO BOUTIQUE | U13: CONCEPCION | V13: HIJA MARJORIE BENITEZ, TRANSPORTE CHEVALIER 13/11 | X13: 958 | Y13: 678 | Z13: 280 | AA13: 0.70772443 | AB13: 23822420 | AC13: 635.95
A14: 7.096.837-1 | B14: 70968371 | C14: GLORIA CECILIA OLIVARES TORRES | D14: CHAÑARAL | E14: MERINO JARPA 590 | F14: 09-98175762 | G14: HECTOR CAFFIERO | H14: g.oltorres91@gmail.com | J14: DANIEL CEA COMPRA Y | L14: 1 | M14: 0 | N14: TUR BUS | Q14: CREDITO 30 Y 60 | S14: TIENDA | T14: EVEN EZER | U14: CHAÑARAL | X14: 118 | Y14: 105 | Z14: 13 | AA14: 0.88983051 | AB14: 2900820 | AC14: 143.75
A15: 7.562.033-0 | B15: 75620330 | C15: PATRICIA BARRIA MANCILLA | D15: PORVENIR | E15: JOHN WILLIAMS 034 | F15: 061-2580171 | G15: SERGIO KRAMARENCO | H15: patricia.barria@gmail.com | J15: PATRICIA BARRIA | N15: TRANSCARGO | Q15: CREDITO 30 Y 60 | T15: ROMY'S | U15: PORVENIR | X15: 0 | Y15: 0 | Z15: 0 | AA15: 0 | AB15: 0 | AC15: 0
A16: 7.634.829-4 | B16: 76348294 | C16: CARLOS MELLA ALVARADO | D16: CASTRO | E16: OHIGGINS 658 | F16: 065-2637291 | G16: PATRICIO CUEVAS | H16: tiendamodafiel@gmail.com | J16: SEÑORA SOFIA | L16: 3 | N16: CRUZ DEL SUR | P16: 0 | Q16: CONTRAFACTURA | R16: 9-5791119 | S16: TIENDA Y PAQUETERIA | T16: MODA FIEL | U16: CASTRO | X16: 229 | Y16: 169 | Z16: 60 | AA16: 0.73799127 | AB16: 5766710 | AC16: 248.4
A17: 7.675.412-8 | B17: 76754128 | C17: IRMA ROMERO CASTRO | D17: CURANILAHUE | E17: ARTURO PRAT 1384 | F17: 041/2691287 | G17: PATRICIO CUEVAS | H17: irmafranciscaromero@gmail.com | I17: IRMAFRANCISCAROMERO@GMAIL.COM | J17: IRMA ROMERO | K17: POP DESPACHADO 12/12 | L17: 3 | M17: 0 | N17: CHEVALIER | Q17: CREDITO 30 Y 60 | S17: BOUTIQUE | T17: FRANCISCA ROMERO BOUTIQUE | U17: CURANILAHUE | X17: 0 | Y17: 0 | Z17: 0 | AA17: 0 | AB17: 0 | AC17: 0
A18: 8.259.662-3 | B18: 82596623 | C18: LUIGI ZANDONAI | D18: LA SERENA | E18: BALMACEDA 423 | F18: 51-215122 | G18: HECTOR CAFFIERO | H18: luigizandonay@hotmail.com | J18: LUIGI ZANDONAI | K18: POP DESPACHADO 12/12 | L18: 3 | M18: 0 | N18: PIERO | Q18: CREDITO 30 Y 60 | S18: TIENDA | T18: TIENDA LUIGI ZANDONAI | U18: =D18 -> LA SERENA | X18: 0 | Y18: 0 | Z18: 0 | AA18: 0 | AB18: 0 | AC18: 48.3
A19: 8.611.778-9 | B19: 86117789 | C19: EMILIA PALMA VILCHES | D19: SAN JAVIER | E19: ARTURO PRAT 2365 | F19: 73-2322862 | G19: CARLOS CUEVAS | H19: mily.palma@gmail.com | J19: MILY PALMA | K19: DUEÑA | L19: 1 | M19: 0 | N19: GEMITA | Q19: CREDITO 30 Y 60 | S19: GRANDES TIENDAS | T19: MILY | U19: SAN JAVIER | V19: SIN INFORMACION COMERCIAL 20/02 | X19: 0 | Y19: 0 | Z19: 0 | AA19: 0 | AB19: 0 | AC19: 0
A20: 8.659.812-4 | B20: 86598124 | C20: RODRIGO EDUARDO SEÑOR LEDESMA | D20: TOME | E20: NOGUEIRA 1137 | F20: 41-2651720 9860610 | G20: PATRICIO CUEVAS | H20: senrodtom@hotmail.com | J20: RODRIGO SEÑOR O MONI | K20: SOCIO | L20: 3 | M20: 0 | N20: VILLA PEAT | Q20: CREDITO 30 Y 60 | S20: VTAS DE PRENDAS DE VESTIR | T20: COMERCIAL LOGROÑO | U20: TOME | V20: SIN INFORMACION COMERCIAL 20/02 | X20: 0 | Y20: 0 | Z20: 0 | AA20: 0 | AB20: 0 | AC20: 0
A21: 8.673.204-1 | B21: 86732041 | C21: ROMAN JUAN CASTRO CAYO | D21: ARICA | E21: AVENIDA 18 DE SEPTIEMBRE 301 L | F21: 58-2232504 | G21: HECTOR CAFFIERO | H21: castro.jade@hotmail.com | J21: ROMAN CASTRO | L21: 1 | M21: 0 | N21: TUR BUS | P21: 0.05 | Q21: CREDITO 30 DIAS | S21: CALZADOS Y ROPAS DE VESTIR | U21: ARICA | X21: 96 | Y21: 73 | Z21: 23 | AA21: 0.76041667 | AB21: 2383040 | AC21: 60.95
A22: 8.780.898-K | B22: 8780898K | C22: PATRICIA HAFON DESMOND | D22: TOCOPILLA | E22: 21 DE MAYO 1549 | F22: 55-812319 | G22: HECTOR CAFFIERO | H22: phafond@hotmail.com | J22: PATRICIA HAFFON | K22: CRISTINA PAGOS | L22: 1 | M22: 0 | N22: RAMOS CHOLELE | Q22: CREDITO 30 Y 60 | S22: BOUTIQUE | U22: =D22 -> TOCOPILLA | X22: 0 | Y22: 0 | Z22: 0 | AA22: 0 | AB22: 0 | AC22: 0
A23: 8.837.310-3 | B23: 88373103 | C23: MARIA FRANCISCA IDE SCHMIDT | D23: LA REINA | E23: CARLOS SILVA VILDOSOLA 93 | F23: 2 27586405 | G23: PATRICIO CUEVAS | H23: franciscaides@hotmail.com | J23: SRA FRANCISCA | K23: POP DESPACHADO 11/12 | L23: 3 | M23: 0 | N23: TUR BUS | Q23: CREDITO 30 Y 60 | S23: BOUTIQUE | T23: BOUTIQUE FRANCISCA IDE | U23: LA REINA | X23: 0 | Y23: 0 | Z23: 0 | AA23: 0 | AB23: 0 | AC23: 0
A24: 8.875.220-1 | B24: 88752201 | C24: ANA MARIA CORTES | D24: HUASCO | E24: PEDRO AGUIRRE CERDA 316 | F24: 51-531308 | G24: HECTOR CAFFIERO | H24: cgonza77@hotmail.com | J24: CARLA GONZALEZ | L24: 2 | M24: 0 | N24: TUR BUS | Q24: CREDITO30 DIAS | S24: TIENDA BAZAR Y PAQUETERIA | T24: ANA MARIA BOUTIQUE | U24: =D24 -> HUASCO | X24: 0 | Y24: 0 | Z24: 0 | AA24: 0 | AB24: 0 | AC24: 0
A25: 8.990.492-7 | B25: 89904927 | C25: LEYLA DEL CAMPO CASTRO | D25: PUERTO AYSEN | E25: ARTURO PRAT 735 | F25: 067-336824 | G25: SERGIO KRAMARENCO | H25: oleyboutique@gmail.com | J25: LEYLA DEL CAMPO | K25: DUEÑA DE LA TIENDA | L25: 3 | M25: 0 | N25: ATE | Q25: TRANSF. CONTRA ENTREGA | S25: BOUTIQUE | T25: OLEY BOUTIQUE | U25: PUERTO AYSEN | X25: 0 | Y25: 0 | Z25: 0 | AA25: 0 | AB25: 0 | AC25: 0
A26: 9.016.604-2 | B26: 90166042 | C26: RODRIGO SALDIVIA REMOLCOY | D26: QUELLON | E26: LADRILLERO 075 | F26: 65/682901 65/683414 | G26: PATRICIO CUEVAS | H26: lucre_esve1@hotmail.com | J26: LUCRESIA ESCANDON | K26: POP DESPACHADO 12/12 | L26: 4 | M26: 0 | N26: CRUZ DEL SUR | Q26: CREDITO 30 Y 60 | X26: 0 | Y26: 0 | Z26: 0 | AA26: 0 | AB26: 0 | AC26: 0
A27: 9.276.152-5 | B27: 92761525 | C27: CARMEN GLORIA GALLARDO VALERIO | D27: LA UNION | E27: COMERCIO 400 | F27: 64-425041 | G27: PATRICIO CUEVAS | H27: ricardo_lmunoz@yahoo.com | J27: RICARDO MUÑOZ | K27: POP DESPACHADO 12/12 | L27: 3 | M27: 0 | N27: CHEVALIER | Q27: CREDITO 30 Y 60 | S27: TIENDA | T27: PIBAS | U27: LA UNION | X27: 252 | Y27: 179 | Z27: 73 | AA27: 0.71031746 | AB27: 6290480 | AC27: 287.5
A28: 9.305.252-8 | B28: 93052528 | C28: SABINA QUISPE PAIRO | D28: ARICA | E28: 18 SEPTIEMBRE 301 LOCAL 4 | F28: 58-251824 LOCAL | G28: HECTOR CAFFIERO | H28: constanzacontreras1310@gmail.com | J28: SABINA QUISPE | K28: MARLON ZAPATA | L28: 1 | M28: 0 | N28: CHACON | Q28: CREDITO 30 Y 60 | S28: BOUTIQUE | T28: SABY SPORT | U28: ARICA | X28: 196 | Y28: 171 | Z28: 25 | AA28: 0.87244898 | AB28: 4906040 | AC28: 439.3
A29: 9.434.963-K | B29: 9434963K | C29: ROSA EMILIA FUENTES MANCILLA | D29: QUEILEN | E29: PEDRO AGUIRRE CERDA 183 | F29: 65/611209 611543 | G29: PATRICIO CUEVAS | H29: rosa.fuentes.23@gmail.com | J29: ROSA FUENTES MANCILL | K29: VERONICA PAGOS | L29: 3 | M29: 0 | N29: CRUZ DEL SUR | Q29: TRANSF. CONTRA ENTREGA | S29: TIENDA | T29: TIENDA Y PAQUETERIA ROCIO | U29: QUEILEN | X29: 0 | Y29: 0 | Z29: 0 | AA29: 0 | AB29: 0 | AC29: 0
A30: 9.684.131-0 | B30: 96841310 | C30: NEDY BASCUNAN MANSILLA | D30: COYHAIQUE | E30: ERRAZURIZ 261-A | F30: 67-245741 | G30: SERGIO KRAMARENCO | H30: nedybascunan@gmail.com | J30: NEDY | K30: 41619 | L30: 1 | M30: 0 | N30: TRANSMAX | Q30: CONTADO | S30: TIENDA | T30: BOUTIQUE FRANCHESCA | U30: COYHAIQUE | X30: 0 | Y30: 0 | Z30: 0 | AA30: 0 | AB30: 0 | AC30: 345
A31: 9.804.121-4 | B31: 98041214 | C31: MARIA CONCHA CACERES | D31: CONSTITUCION | E31: VIAL 380 A | F31: 71-2673006 | G31: PATRICIO CUEVAS | H31: mariaconcha-63@hotmail.co | J31: MARIA CONCHA CACERES | K31: DUEÑA | L31: 3 | M31: 0 | N31: EMECOL | Q31: CREDITO 30 Y 60 | S31: TIENDA | T31: TRIBAL | U31: CONSTITUCION | X31: 0 | Y31: 0 | Z31: 0 | AA31: 0 | AB31: 0 | AC31: 0
A32: 10.026.410-2 | B32: 100264102 | C32: GLORIA CONTRERAS TORRES | D32: COCHRANNE | E32: RIO COLONIAL 560 | F32: 67-552734 | G32: SERGIO KRAMARENCO | H32: gcontrerastorres@hotmail.cl | J32: GLORIA CONTRERAS | L32: 3 | M32: 0 | N32: ATE | Q32: TRANSF. CONTRA ENTREGA | S32: VENTAS PRENDAS DE VESTIR | U32: COCHRANE | V32: DICOM OK AL 27/2 | X32: 0 | Y32: 0 | Z32: 0 | AA32: 0 | AB32: 0 | AC32: 37.95
A33: 10.270.508-4 | B33: 102705084 | C33: ELIANA VENTURELLI REGLA | D33: CAP. PASTENE | E33: PEDRO MONTT 640 | F33: 84092579 | G33: PATRICIO CUEVAS | H33: elianaventurelliregla@hotmail. | J33: ELIANA VENTURELLI | K33: POP DESPACHADO 12/12 | L33: 3 | M33: 0 | N33: JC | Q33: CHEQUE 30 DIAS | S33: BOUTIQUE | U33: TRAIGUEN | V33: SIN INFORMACION COMERCIAL 20/02 | X33: 64 | Y33: 62 | Z33: 2 | AA33: 0.96875 | AB33: 1573360 | AC33: 36.8
A34: 10.529.776-9 | B34: 105297769 | C34: OLGA OLIVIA POBLETE CONCHA | D34: TRAIGUEN | E34: LAGOS 957 | F34: 950866511 | G34: CARLOS CUEVAS | H34: OLGAPOBLETECONCHA@GMAIL.COM | J34: OLGA POBLETE | L34: 3 | N34: BUSES JC | Q34: TRANSF. CONTRAFACTURA | R34: 0 | S34: BOUTIQUE | T34: FENIX BOUTIQUE | X34: 96 | Y34: 70 | Z34: 26 | AA34: 0.72916667 | AB34: 2423040 | AC34: 70.15
A35: 10.777.684-2 | B35: 107776842 | C35: KETTY ROJAS RAMIREZ | D35: COPIAPO | E35: VILLA DIEGO PORTALES C/11 | F35: 052/241236 | G35: HECTOR CAFFIERO | H35: krojasramirez@gmail.com | L35: 4 | M35: 0 | N35: ENVIAS EXPRESS | Q35: CREDITO 30 Y 60 | S35: TIENDA | X35: 0 | Y35: 0 | Z35: 0 | AA35: 0 | AB35: 0 | AC35: 0
A36: 10.879.819-K | B36: 10879819K | C36: CELIA VASQUEZ BARRERA | D36: VILLARRICA | E36: PEDRO DE VALDIVIA 650 LOCAL 25 | F36: 045-2412431 | G36: PATRICIO CUEVAS | H36: prodigos@live.cl | J36: CELIA VASQUEZ | K36: POP DESPACHADO 11/12 | L36: 1 | M36: 0 | N36: TUR BUS | P36: 0.05 | Q36: CONTADO | T36: PRODIGOS | U36: VILLARRICA | V36: NO CUMPLE PERFIL PARA MOHICANO | X36: 58 | Y36: 56 | Z36: 2 | AA36: 0.96551724 | AB36: 1441420 | AC36: 49.45
A37: 11.354.049-4 | B37: 113540494 | C37: PATRICIA MENA SANDOVAL | D37: TRAIGUEN | E37: AV SAAVEDRA 460 | F37: 045-861873 | G37: PATRICIO CUEVAS | H37: patcemesa@hotmail.com | J37: PATRICIA MENA | L37: 3 | M37: 0 | Q37: CREDITO 30 Y 60 | S37: BOUTIQUE | T37: PATY MENA BOUTIQUE | U37: TRAIGUEN | X37: 0 | Y37: 0 | Z37: 0 | AA37: 0 | AB37: 0 | AC37: 0
A38: 11.407.997-9 | B38: 114079979 | C38: DANITZA OSSES AEDO | D38: TRAIGUEN | E38: CALLE SANTA CRUZ Nº 807 | F38: 45-861192 | G38: PATRICIO CUEVAS | H38: danitzaosses@hotmail.com | J38: DANITZA OSSES | K38: DUEÑA | L38: 3 | M38: 0 | Q38: CREDITO 30 Y 60 | V38: TRANSPORTES JAC , SIN INFORMES COMERCIALES 20/02 | X38: 73 | Y38: 63 | Z38: 10 | AA38: 0.8630137 | AB38: 1798270 | AC38: 50.6
A39: 11.564.359-2 | B39: 115643592 | C39: BELLA FUENTES PINCHEIRA | D39: LINARES | E39: CHACABUCO 435 LOCAL 03 | F39: 73-2219931 | G39: PATRICIO CUEVAS | H39: befupi@gmail.com | J39: BELLA FUENTES | K39: POP DESPACHADO 12/12 | L39: 1 | M39: 0 | N39: CHEVALIER | P39: 0.05 | Q39: CONTADO | R39: 98376422 | S39: BOUTIQUE BAZAR Y PAQUETERIA | T39: D JAVI | U39: LINARES | V39: CANCELA CHEQUE 30 DIAS CON 10% DE DESCUENTO, SU ENCARGADA DE LOCAL ES MINERVA | X39: 480 | Y39: 446 | Z39: 34 | AA39: 0.92916667 | AB39: 11887200 | AC39: 500.25
A40: 11.684.129-0 | B40: 116841290 | C40: HUGO MONTERO FIGUEROA | D40: LOS ANGELES | E40: VALDIVIA 487 LOCAL L | G40: PATRICIO CUEVAS | H40: hugomonterof@yahoo.es | J40: HUGO MONTERO | K40: DUEÑO | L40: 1 | M40: 0 | N40: CHEVALIER | Q40: 30 DIAS | R40: 09-3447832 | S40: TIENDAS | T40: HECHIZOS | U40: LOS ANGELES | V40: TRANSPORTE CHEVALIER | X40: 335 | Y40: 330 | Z40: 5 | AA40: 0.98507463 | AB40: 8369650 | AC40: 385.25
A41: 12.003.736-6 | B41: 120037366 | C41: ARMANDO BARRIA LEGUE | D41: PUERTO NATALES | E41: MANUEL BULNES 731 LOCAL A | F41: 061-413977 | G41: SERGIO KRAMARENCO | H41: tiendarmando@gmial.com | J41: ARMANDO BARRIA | L41: 3 | M41: 0 | N41: TRANSCARGO | Q41: TRANSF. CONTRA ENTREGA | S41: TIENDA | T41: ESPACIO JEANS | U41: PUERTO NATALES | X41: 182 | Y41: 181 | Z41: 1 | AA41: 0.99450549 | AB41: 4475180 | AC41: 218.5
...

Sheet BASE DE DATOS OFICIAL
A1: 1 | B1: 1 | C1: 2 | D1: 3 | E1: 4 | F1: 5 | G1: 6 | H1: 7 | I1: 8 | J1: 9 | K1: 10 | L1: 11 | M1: 12 | N1: 13 | O1: 14 | P1: 15 | Q1: 16 | R1: 17 | S1: 18 | T1: 19 | U1: 20 | V1: 21 | W1: 22 | X1: 23 | Y1: 24 | Z1: 25 | AA1: 26 | AB1: 27 | AC1: 28
A3: RUT | B3: RUT2 | C3: Razon Social | D3: Ciudad | E3: Direccion | F3: Fono | G3: Vendedor | H3: Correo | I3: WWW | J3: Contacto | K3: Cargo | L3: GRUPO | M3: Credito | N3: Transporte | O3: BLOQUEADO | P3: Dcto | Q3: CONDICION DE PAGO | R3: CELULAR | S3: GIRO | T3: NOMBRE DE TIENDA | U3: COMUNA | V3: Observaciones | W3: Ped_anterior | X3: Cantidad | Y3: Despacho | Z3: Saldo | AA3: % Despacho | AB3: Valor | AC3: Meta Cole-38
A4: 4.878.758-4 | B4: 48787584 | C4: ROBERTO KOBUS PEMSO | D4: ANCUD | E4: PUDETO 143-145 | F4: 998269854 | G4: PATRICIO CUEVAS | H4: tiendasmachos@gmail.com | I4: MACHOS BOUTIQUE@SURNET.CL | J4: JENIFER PAGOS | L4: 4 | M4: 0 | N4: VARMONTT | Q4: CREDITO 30 Y 60 | S4: GRANDES TIENDAS | T4: MACHOS | U4: ANCUD | V4: VARMONTT | X4: 505 | Y4: 438 | Z4: =SUM(X4-Y4) -> 67 | AA4: 0.88706366 | AB4: 11150620 | AC4: 782
A5: 5.001.562-9 | B5: 50015629 | C5: INES VARGAS PINO | D5: COPIAPO | E5: ATACAMA 461-A | F5: 52-213939 | G5: HECTOR CAFFIERO | J5: INES VARGAS | L5: 3 | M5: 0 | N5: SER VALL | P5: 0.05 | Q5: TRANSF. CONTRA FACTURA | R5: 8-8637797 | S5: TIENDA DE VESTIR | T5: BOUTIQUE GEMINIS | U5: COPIAPO | X5: 0 | Y5: 0 | Z5: =SUM(X5-Y5) -> 0 | AA5: 0 | AB5: 0 | AC5: 0
A6: 5.384.900-8 | B6: 53849008 | C6: ELIANA RIQUELME R. | D6: FUTRONO | E6: BALMACEDA 249 | F6: 966322618 | G6: PATRICIO CUEVAS | J6: ELIANA RIQUELME | L6: 4 | M6: 0 | N6: TUR BUS | Q6: CREDITO 30 Y 60 | S6: VENTAS | T6: COSAS BOUTIQUE | U6: FUTRONO | X6: 0 | Y6: 0 | Z6: =SUM(X6-Y6) -> 0 | AA6: 0 | AB6: 0 | AC6: 0
A7: 5.913.365-9 | B7: 59133659 | C7: ANA MARIA MANFREDI CARRASCO | D7: OVALLE | E7: VICUÑA MACKENNA 287 | F7: 053-622626 | G7: HECTOR CAFFIERO | H7: manfredi@hotmail.com | J7: DANIELA O ANA MARIA | K7: DUEÑO | L7: 3 | M7: 0 | N7: CHILE LINDO | Q7: CREDITO 30 Y 60 | S7: VENTAS AL POR MENOR | T7: BOUTIQUE PARA TI | U7: =D7 -> OVALLE | X7: 118 | Y7: 107 | Z7: =SUM(X7-Y7) -> 11 | AA7: 0.63736264 | AB7: 2688930 | AC7: 186.3
A8: 6.031.123-4 | B8: 60311234 | C8: FABIOLA BENAVENTE MEZA | D8: PARRAL | E8: ANIBAL PINTO 590 | F8: 961895384 | G8: CARLOS CUEVAS | H8: tiendaelegance@gmail.com | J8: FABIOLA BENAVENTE | K8: POP DESPACHADO 11/12 | L8: 3 | M8: 0 | N8: VILLA PRAT | Q8: CONTRAFACTURA | S8: BOUTIQUE | T8: ELEGANTE BOUTIQUE | U8: PARRAL | X8: 62 | Y8: 55 | Z8: =SUM(X8-Y8) -> 7 | AA8: 0.97777778 | AB8: 1399450 | AC8: 51.75
A9: 6.331.910-4 | B9: 63319104 | C9: LUIS SOUMASTRE RAMIREZ | D9: ARICA | E9: 21 DE MAYO 454 | F9: 058-2232959 | G9: HECTOR CAFFIERO | H9: lfsr24@hotmail.com | J9: gloria tapia | L9: 3 | M9: 0 | N9: CHACON | Q9: CREDITO 30 Y 60 | S9: VENTAS AL POR MENOR | U9: ARICA | X9: 71 | Y9: 65 | Z9: =SUM(X9-Y9) -> 6 | AA9: 0 | AB9: 1665350 | AC9: 26.45
A10: 6.589.904-3 | B10: 65899043 | C10: ANITA BERTA GADICKE | D10: OSORNO | E10: OHIGGINS 534 | F10: 985067217 | G10: PATRICIO CUEVAS | H10: anitagadicke@gmail.com | J10: ANITA GADICKE | L10: 4 | M10: 0 | N10: CIDHER | Q10: CREDITO 30 Y 60 | S10: BOUTIQUE | T10: ALBANY SPORT | U10: OSORNO | X10: 0 | Y10: 0 | Z10: =SUM(X10-Y10) -> 0 | AA10: 0 | AB10: 0 | AC10: 0
A11: 6.775.324-0 | B11: 67753240 | C11: MARIA DE LOS ANGELES DIAZ BELLIDO | D11: VILLA ALEMANA | E11: BUENOS AIRE 845 | F11: 32-2951011 | G11: PATRICIO CUEVAS | H11: balaustros2@hotmail.com | I11: BALASUTROSVILLAALEMANA@GMAIL.C | J11: MARIA DE LOS ANGELES | L11: 4 | N11: ABC | Q11: CREDITO 30 Y 60 | S11: BOUTIQUE | T11: BALAUSTROS BOUTIQUE | U11: VILLA ALEMANA | X11: 0 | Y11: 0 | Z11: =SUM(X11-Y11) -> 0 | AA11: 0 | AB11: 0 | AC11: 0
A12: 6.799.967-3 | B12: 67999673 | C12: ANA MARIA SALVATIERRA TAPIA | D12: CABILDO | E12: HUMERES 727 | F12: 91286053 | G12: CARLOS CUEVAS | H12: anisalta@hotmail.com | J12: ANA MARIA SALVATIERR | L12: 3 | M12: 0 | N12: TUR BUS | Q12: CREDITO 30 Y 60 | S12: BOUTIQUE | T12: BOUTIQUE ANITA | U12: CABILDO | X12: 36 | Y12: 36 | Z12: =SUM(X12-Y12) -> 0 | AA12: 0.97777778 | AB12: 917640 | AC12: 216.2
A13: 76.965.431-3 | B13: 769654313 | C13: OPALO VESTUARIO | D13: CONCEPCION | E13: BARROS ARANA 815 LOCAL 14 | F13: 991959818 | G13: PATRICIO CUEVAS | H13: mayobenites@hotmail.com | J13: HILIA CONCHA | K13: DUEÑA | L13: 1 | M13: 0 | N13: CHEVALIER | Q13: CHEQUE 30 DIAS | R13: 99594046 | S13: BOUTIQUE | T13: OPALO BOUTIQUE | U13: CONCEPCION | V13: HIJA MARJORIE BENITEZ, TRANSPORTE CHEVALIER 13/11 | X13: 704 | Y13: 555 | Z13: =SUM(X13-Y13) -> 149 | AA13: 0.70772443 | AB13: 14347450 | AC13: 635.95
A14: 7.096.837-1 | B14: 70968371 | C14: GLORIA CECILIA OLIVARES TORRES | D14: CHAÑARAL | E14: MERINO JARPA 590 | F14: 09-98175762 | G14: HECTOR CAFFIERO | H14: g.oltorres91@gmail.com | J14: DANIEL CEA COMPRA Y | L14: 1 | M14: 0 | N14: TUR BUS | Q14: CREDITO 30 Y 60 | S14: TIENDA | T14: EVEN EZER | U14: CHAÑARAL | X14: 130 | Y14: 125 | Z14: =SUM(X14-Y14) -> 5 | AA14: 0.88983051 | AB14: 3238750 | AC14: 143.75
A15: 7.562.033-0 | B15: 75620330 | C15: PATRICIA BARRIA MANCILLA | D15: PORVENIR | E15: JOHN WILLIAMS 034 | F15: 061-2580171 | G15: SERGIO KRAMARENCO | H15: patricia.barria@gmail.com | J15: PATRICIA BARRIA | N15: TRANSCARGO | Q15: CREDITO 30 Y 60 | T15: ROMY'S | U15: PORVENIR | X15: 0 | Y15: 0 | Z15: =SUM(X15-Y15) -> 0 | AA15: 0 | AB15: 0 | AC15: 0
A16: 7.634.829-4 | B16: 76348294 | C16: CARLOS MELLA ALVARADO | D16: CASTRO | E16: OHIGGINS 658 | F16: 065-2637291 | G16: PATRICIO CUEVAS | H16: tiendamodafiel@gmail.com | J16: SEÑORA SOFIA | L16: 3 | N16: CRUZ DEL SUR | P16: 0 | Q16: CONTRAFACTURA | R16: 9-5791119 | S16: TIENDA Y PAQUETERIA | T16: MODA FIEL | U16: CASTRO | X16: 259 | Y16: 221 | Z16: =SUM(X16-Y16) -> 38 | AA16: 0.73799127 | AB16: 5596790 | AC16: 248.4
A17: 7.675.412-8 | B17: 76754128 | C17: IRMA ROMERO CASTRO | D17: CURANILAHUE | E17: ARTURO PRAT 1384 | F17: 041/2691287 | G17: PATRICIO CUEVAS | H17: irmafranciscaromero@gmail.com | I17: IRMAFRANCISCAROMERO@GMAIL.COM | J17: IRMA ROMERO | K17: POP DESPACHADO 12/12 | L17: 3 | M17: 0 | N17: CHEVALIER | Q17: CREDITO 30 Y 60 | S17: BOUTIQUE | T17: FRANCISCA ROMERO BOUTIQUE | U17: CURANILAHUE | X17: 0 | Y17: 0 | Z17: =SUM(X17-Y17) -> 0 | AA17: 0 | AB17: 0 | AC17: 0
A18: 8.259.662-3 | B18: 82596623 | C18: LUIGI ZANDONAI | D18: LA SERENA | E18: BALMACEDA 423 | F18: 51-215122 | G18: HECTOR CAFFIERO | H18: luigizandonay@hotmail.com | J18: LUIGI ZANDONAI | K18: POP DESPACHADO 12/12 | L18: 3 | M18: 0 | N18: PIERO | Q18: CREDITO 30 Y 60 | S18: TIENDA | T18: TIENDA LUIGI ZANDONAI | U18: =D18 -> LA SERENA | X18: 0 | Y18: 0 | Z18: =SUM(X18-Y18) -> 0 | AA18: 0 | AB18: 0 | AC18: 48.3
A19: 8.611.778-9 | B19: 86117789 | C19: EMILIA PALMA VILCHES | D19: SAN JAVIER | E19: ARTURO PRAT 2365 | F19: 73-2322862 | G19: CARLOS CUEVAS | H19: mily.palma@gmail.com | J19: MILY PALMA | K19: DUEÑA | L19: 1 | M19: 0 | N19: GEMITA | Q19: CREDITO 30 Y 60 | S19: GRANDES TIENDAS | T19: MILY | U19: SAN JAVIER | V19: SIN INFORMACION COMERCIAL 20/02 | X19: 0 | Y19: 0 | Z19: =SUM(X19-Y19) -> 0 | AA19: 0 | AB19: 0 | AC19: 0
A20: 8.659.812-4 | B20: 86598124 | C20: RODRIGO EDUARDO SEÑOR LEDESMA | D20: TOME | E20: NOGUEIRA 1137 | F20: 41-2651720 9860610 | G20: PATRICIO CUEVAS | H20: senrodtom@hotmail.com | J20: RODRIGO SEÑOR O MONI | K20: SOCIO | L20: 3 | M20: 0 | N20: VILLA PEAT | Q20: CREDITO 30 Y 60 | S20: VTAS DE PRENDAS DE VESTIR | T20: COMERCIAL LOGROÑO | U20: TOME | V20: SIN INFORMACION COMERCIAL 20/02 | X20: 0 | Y20: 0 | Z20: =SUM(X20-Y20) -> 0 | AA20: 0 | AB20: 0 | AC20: 0
A21: 8.673.204-1 | B21: 86732041 | C21: ROMAN JUAN CASTRO CAYO | D21: ARICA | E21: AVENIDA 18 DE SEPTIEMBRE 301 L | F21: 58-2232504 | G21: HECTOR CAFFIERO | H21: castro.jade@hotmail.com | J21: ROMAN CASTRO | L21: 1 | M21: 0 | N21: TUR BUS | P21: 0.05 | Q21: CREDITO 30 DIAS | S21: CALZADOS Y ROPAS DE VESTIR | U21: ARICA | X21: 41 | Y21: 42 | Z21: =SUM(X21-Y21) -> -1 | AA21: 0.76041667 | AB21: 1057580 | AC21: 60.95
A22: 8.780.898-K | B22: 8780898K | C22: PATRICIA HAFON DESMOND | D22: TOCOPILLA | E22: 21 DE MAYO 1549 | F22: 55-812319 | G22: HECTOR CAFFIERO | H22: phafond@hotmail.com | J22: PATRICIA HAFFON | K22: CRISTINA PAGOS | L22: 1 | M22: 0 | N22: RAMOS CHOLELE | Q22: CREDITO 30 Y 60 | S22: BOUTIQUE | U22: =D22 -> TOCOPILLA | X22: 8 | Y22: 0 | Z22: =SUM(X22-Y22) -> 8 | AA22: 0 | AB22: 0 | AC22: 0
A23: 8.837.310-3 | B23: 88373103 | C23: MARIA FRANCISCA IDE SCHMIDT | D23: LA REINA | E23: CARLOS SILVA VILDOSOLA 93 | F23: 2 27586405 | G23: PATRICIO CUEVAS | H23: franciscaides@hotmail.com | J23: SRA FRANCISCA | K23: POP DESPACHADO 11/12 | L23: 3 | M23: 0 | N23: TUR BUS | Q23: CREDITO 30 Y 60 | S23: BOUTIQUE | T23: BOUTIQUE FRANCISCA IDE | U23: LA REINA | X23: 0 | Y23: 0 | Z23: =SUM(X23-Y23) -> 0 | AA23: 0 | AB23: 0 | AC23: 0
A24: 8.875.220-1 | B24: 88752201 | C24: ANA MARIA CORTES | D24: HUASCO | E24: PEDRO AGUIRRE CERDA 316 | F24: 51-531308 | G24: HECTOR CAFFIERO | H24: cgonza77@hotmail.com | J24: CARLA GONZALEZ | L24: 2 | M24: 0 | N24: TUR BUS | Q24: CREDITO30 DIAS | S24: TIENDA BAZAR Y PAQUETERIA | T24: ANA MARIA BOUTIQUE | U24: =D24 -> HUASCO | X24: 0 | Y24: 0 | Z24: =SUM(X24-Y24) -> 0 | AA24: 0 | AB24: 0 | AC24: 0
A25: 8.990.492-7 | B25: 89904927 | C25: LEYLA DEL CAMPO CASTRO | D25: PUERTO AYSEN | E25: ARTURO PRAT 735 | F25: 067-336824 | G25: SERGIO KRAMARENCO | H25: oleyboutique@gmail.com | J25: LEYLA DEL CAMPO | K25: DUEÑA DE LA TIENDA | L25: 3 | M25: 0 | N25: ATE | Q25: TRANSF. CONTRA ENTREGA | S25: BOUTIQUE | T25: OLEY BOUTIQUE | U25: PUERTO AYSEN | X25: 0 | Y25: 0 | Z25: =SUM(X25-Y25) -> 0 | AA25: 0 | AB25: 0 | AC25: 0
A26: 9.016.604-2 | B26: 90166042 | C26: RODRIGO SALDIVIA REMOLCOY | D26: QUELLON | E26: LADRILLERO 075 | F26: 65/682901 65/683414 | G26: PATRICIO CUEVAS | H26: lucre_esve1@hotmail.com | J26: LUCRESIA ESCANDON | K26: POP DESPACHADO 12/12 | L26: 4 | M26: 0 | N26: CRUZ DEL SUR | Q26: CREDITO 30 Y 60 | X26: 0 | Y26: 0 | Z26: =SUM(X26-Y26) -> 0 | AA26: 0 | AB26: 0 | AC26: 0
A27: 9.276.152-5 | B27: 92761525 | C27: CARMEN GLORIA GALLARDO VALERIO | D27: LA UNION | E27: COMERCIO 400 | F27: 64-425041 | G27: PATRICIO CUEVAS | H27: ricardo_lmunoz@yahoo.com | J27: RICARDO MUÑOZ | K27: POP DESPACHADO 12/12 | L27: 3 | M27: 0 | N27: CHEVALIER | Q27: CREDITO 30 Y 60 | S27: TIENDA | T27: PIBAS | U27: LA UNION | X27: 121 | Y27: 106 | Z27: =SUM(X27-Y27) -> 15 | AA27: 0.71031746 | AB27: 2771940 | AC27: 287.5
A28: 9.305.252-8 | B28: 93052528 | C28: SABINA QUISPE PAIRO | D28: ARICA | E28: 18 SEPTIEMBRE 301 LOCAL 4 | F28: 58-251824 LOCAL | G28: HECTOR CAFFIERO | H28: constanzacontreras1310@gmail.com | J28: SABINA QUISPE | K28: MARLON ZAPATA | L28: 1 | M28: 0 | N28: CHACON | Q28: CREDITO 30 Y 60 | S28: BOUTIQUE | T28: SABY SPORT | U28: ARICA | X28: 553 | Y28: 441 | Z28: =SUM(X28-Y28) -> 112 | AA28: 0.87244898 | AB28: 11312590 | AC28: 439.3
A29: 9.434.963-K | B29: 9434963K | C29: ROSA EMILIA FUENTES MANCILLA | D29: QUEILEN | E29: PEDRO AGUIRRE CERDA 183 | F29: 65/611209 611543 | G29: PATRICIO CUEVAS | H29: rosa.fuentes.23@gmail.com | J29: ROSA FUENTES MANCILL | K29: VERONICA PAGOS | L29: 3 | M29: 0 | N29: CRUZ DEL SUR | Q29: TRANSF. CONTRA ENTREGA | S29: TIENDA | T29: TIENDA Y PAQUETERIA ROCIO | U29: QUEILEN | X29: 0 | Y29: 0 | Z29: =SUM(X29-Y29) -> 0 | AA29: 0 | AB29: 0 | AC29: 0
A30: 9.684.131-0 | B30: 96841310 | C30: NEDY BASCUNAN MANSILLA | D30: COYHAIQUE | E30: ERRAZURIZ 261-A | F30: 67-245741 | G30: SERGIO KRAMARENCO | H30: nedybascunan@gmail.com | J30: NEDY | K30: 41619 | L30: 1 | M30: 0 | N30: TRANSMAX | Q30: CONTADO | S30: TIENDA | T30: BOUTIQUE FRANCHESCA | U30: COYHAIQUE | X30: 0 | Y30: 0 | Z30: =SUM(X30-Y30) -> 0 | AA30: 0 | AB30: 0 | AC30: 345
A31: 9.804.121-4 | B31: 98041214 | C31: MARIA CONCHA CACERES | D31: CONSTITUCION | E31: VIAL 380 A | F31: 71-2673006 | G31: PATRICIO CUEVAS | H31: mariaconcha-63@hotmail.co | J31: MARIA CONCHA CACERES | K31: DUEÑA | L31: 3 | M31: 0 | N31: EMECOL | Q31: CREDITO 30 Y 60 | S31: TIENDA | T31: TRIBAL | U31: CONSTITUCION | X31: 0 | Y31: 0 | Z31: =SUM(X31-Y31) -> 0 | AA31: 0 | AB31: 0 | AC31: 0
A32: 10.026.410-2 | B32: 100264102 | C32: GLORIA CONTRERAS TORRES | D32: COCHRANNE | E32: RIO COLONIAL 560 | F32: 67-552734 | G32: SERGIO KRAMARENCO | H32: gcontrerastorres@hotmail.cl | J32: GLORIA CONTRERAS | L32: 3 | M32: 0 | N32: ATE | Q32: TRANSF. CONTRA ENTREGA | S32: VENTAS PRENDAS DE VESTIR | U32: COCHRANE | V32: DICOM OK AL 27/2 | X32: 0 | Y32: 0 | Z32: =SUM(X32-Y32) -> 0 | AA32: 0 | AB32: 0 | AC32: 37.95
A33: 10.270.508-4 | B33: 102705084 | C33: ELIANA VENTURELLI REGLA | D33: CAP. PASTENE | E33: PEDRO MONTT 640 | F33: 84092579 | G33: PATRICIO CUEVAS | H33: elianaventurelliregla@hotmail. | J33: ELIANA VENTURELLI | K33: POP DESPACHADO 12/12 | L33: 3 | M33: 0 | N33: JC | Q33: CHEQUE 30 DIAS | S33: BOUTIQUE | U33: TRAIGUEN | V33: SIN INFORMACION COMERCIAL 20/02 | X33: 190 | Y33: 121 | Z33: =SUM(X33-Y33) -> 69 | AA33: 0.96875 | AB33: 3051790 | AC33: 36.8
A34: 10.529.776-9 | B34: 105297769 | C34: OLGA OLIVIA POBLETE CONCHA | D34: TRAIGUEN | E34: LAGOS 957 | F34: 950866511 | G34: CARLOS CUEVAS | H34: OLGAPOBLETECONCHA@GMAIL.COM | J34: OLGA POBLETE | L34: 3 | N34: BUSES JC | Q34: TRANSF. CONTRAFACTURA | R34: 0 | S34: BOUTIQUE | T34: FENIX BOUTIQUE | X34: 96 | Y34: 70 | Z34: =SUM(X34-Y34) -> 26 | AA34: 0.72916667 | AB34: 2423040 | AC34: 70.15
A35: 10.777.684-2 | B35: 107776842 | C35: KETTY ROJAS RAMIREZ | D35: COPIAPO | E35: VILLA DIEGO PORTALES C/11 | F35: 052/241236 | G35: HECTOR CAFFIERO | H35: krojasramirez@gmail.com | L35: 4 | M35: 0 | N35: ENVIAS EXPRESS | Q35: CREDITO 30 Y 60 | S35: TIENDA | X35: 0 | Y35: 0 | Z35: =SUM(X35-Y35) -> 0 | AA35: 0 | AB35: 0 | AC35: 0
A36: 10.879.819-K | B36: 10879819K | C36: CELIA VASQUEZ BARRERA | D36: VILLARRICA | E36: PEDRO DE VALDIVIA 650 LOCAL 25 | F36: 045-2412431 | G36: PATRICIO CUEVAS | H36: prodigos@live.cl | J36: CELIA VASQUEZ | K36: POP DESPACHADO 11/12 | L36: 1 | M36: 0 | N36: TUR BUS | P36: 0.05 | Q36: CONTADO | T36: PRODIGOS | U36: VILLARRICA | V36: NO CUMPLE PERFIL PARA MOHICANO | X36: 49 | Y36: 40 | Z36: =SUM(X36-Y36) -> 9 | AA36: 0.96551724 | AB36: 1006600 | AC36: 49.45
A37: 11.354.049-4 | B37: 113540494 | C37: PATRICIA MENA SANDOVAL | D37: TRAIGUEN | E37: AV SAAVEDRA 460 | F37: 045-861873 | G37: PATRICIO CUEVAS | H37: patcemesa@hotmail.com | J37: PATRICIA MENA | L37: 3 | M37: 0 | Q37: CREDITO 30 Y 60 | S37: BOUTIQUE | T37: PATY MENA BOUTIQUE | U37: TRAIGUEN | X37: 0 | Y37: 0 | Z37: =SUM(X37-Y37) -> 0 | AA37: 0 | AB37: 0 | AC37: 0
A38: 11.407.997-9 | B38: 114079979 | C38: DANITZA OSSES AEDO | D38: TRAIGUEN | E38: CALLE SANTA CRUZ Nº 807 | F38: 45-861192 | G38: PATRICIO CUEVAS | H38: danitzaosses@hotmail.com | J38: DANITZA OSSES | K38: DUEÑA | L38: 3 | M38: 0 | Q38: CREDITO 30 Y 60 | V38: TRANSPORTES JAC , SIN INFORMES COMERCIALES 20/02 | X38: 106 | Y38: 95 | Z38: =SUM(X38-Y38) -> 11 | AA38: 0.8630137 | AB38: 2438050 | AC38: 50.6
A39: 11.564.359-2 | B39: 115643592 | C39: BELLA FUENTES PINCHEIRA | D39: LINARES | E39: CHACABUCO 435 LOCAL 03 | F39: 73-2219931 | G39: PATRICIO CUEVAS | H39: befupi@gmail.com | J39: BELLA FUENTES | K39: POP DESPACHADO 12/12 | L39: 1 | M39: 0 | N39: CHEVALIER | P39: 0.05 | Q39: CONTADO | R39: 98376422 | S39: BOUTIQUE BAZAR Y PAQUETERIA | T39: D JAVI | U39: LINARES | V39: CANCELA CHEQUE 30 DIAS CON 10% DE DESCUENTO, SU ENCARGADA DE LOCAL ES MINERVA | X39: 623 | Y39: 497 | Z39: =SUM(X39-Y39) -> 126 | AA39: 0.92916667 | AB39: 12767030 | AC39: 500.25
A40: 11.684.129-0 | B40: 116841290 | C40: HUGO MONTERO FIGUEROA | D40: LOS ANGELES | E40: VALDIVIA 487 LOCAL L | G40: PATRICIO CUEVAS | H40: hugomonterof@yahoo.es | J40: HUGO MONTERO | K40: DUEÑO | L40: 1 | M40: 0 | N40: CHEVALIER | Q40: 30 DIAS | R40: 09-3447832 | S40: TIENDAS | T40: HECHIZOS | U40: LOS ANGELES | V40: TRANSPORTE CHEVALIER | X40: 397 | Y40: 380 | Z40: =SUM(X40-Y40) -> 17 | AA40: 0.98507463 | AB40: 9639200 | AC40: 385.25
A41: 12.003.736-6 | B41: 120037366 | C41: ARMANDO BARRIA LEGUE | D41: PUERTO NATALES | E41: MANUEL BULNES 731 LOCAL A | F41: 061-413977 | G41: SERGIO KRAMARENCO | H41: tiendarmando@gmial.com | J41: ARMANDO BARRIA | L41: 3 | M41: 0 | N41: TRANSCARGO | Q41: TRANSF. CONTRA ENTREGA | S41: TIENDA | T41: ESPACIO JEANS | U41: PUERTO NATALES | X41: 70 | Y41: 57 | Z41: =SUM(X41-Y41) -> 13 | AA41: 0.99450549 | AB41: 1447430 | AC41: 218.5
...

Sheet BD_COMPARATIVA
A1: RUT | B1: RAZON SOCIAL | C1: COD VEN | D1: VENDEDOR | E1: CIUDAD | F1: CANTIDAD T:38 | G1: VALOR T:38 | H1: FACTURADO T:38 | I1: VALOR FACT. T:38
A2: 48787584 | B2: ROBERTO KOBUS PEMSO | C2: 2 | D2: PATRICIO CUEVAS | E2: ANCUD | F2: 505 | G2: 12867950 | H2: 438 | I2: 11150620
A3: 59133659 | B3: ANA MARIA MANFREDI CARRASCO | C3: 6 | D3: HECTOR CAFFIERO VASQUEZ | E3: OVALLE | F3: 118 | G3: 2963820 | H3: 107 | I3: 2688930
A4: 60311234 | B4: FABIOLA BENAVENTE MEZA | C4: 12 | D4: CARLOS CUEVAS | E4: PARRAL | F4: 62 | G4: 1574380 | H4: 55 | I4: 1399450
A5: 60921830 | B5: NORA BARRAZA MILLA | C5: 6 | D5: HECTOR CAFFIERO VASQUEZ | E5: DIEGO DE ALMAGRO | F5: 67 | G5: 1737330 | H5: 60 | I5: 1562400
A6: 63319104 | B6: LUIS SOUMASTRE RAMIREZ | C6: 6 | D6: HECTOR CAFFIERO VASQUEZ | E6: ARICA | F6: 71 | G6: 1821290 | H6: 65 | I6: 1665350
A7: 67999673 | B7: ANA MARIA SALVATIERRA TAPIA | C7: 2 | D7: PATRICIO CUEVAS | E7: CABILDO | F7: 36 | G7: 917640 | H7: 36 | I7: 917640
A8: 70968371 | B8: GLORIA CECILIA OLIVARES TORRES | C8: 6 | D8: HECTOR CAFFIERO VASQUEZ | E8: CHAﾑARAL | F8: 130 | G8: 3367700 | H8: 125 | I8: 3238750
A9: 71650685 | B9: SERGIO HERNAN CERDA ESCOBAR | C9: 2 | D9: PATRICIO CUEVAS | E9: LOS ANGELES | F9: 290 | G9: 7297100 | H9: 138 | I9: 3473620
A10: 72952936 | B10: ANA SAAVEDRA ORTIZ | C10: 12 | D10: CARLOS CUEVAS | E10: CAﾑETE | F10: 104 | G10: 2694960 | H10: 93 | I10: 2418070
A11: 75099215 | B11: NOLBERTO AVILA CORTES | C11: 2 | D11: PATRICIO CUEVAS | E11: CAUQUENES | F11: 166 | G11: 4210340 | H11: 163 | I11: 4135370
A12: 76348294 | B12: CARLOS MELLA ALVARADO | C12: 2 | D12: PATRICIO CUEVAS | E12: 2 | F12: 259 | G12: 6558410 | H12: 221 | I12: 5596790
A13: 81838518 | B13: CLARA VARGAS NATER | C13: 12 | D13: CARLOS CUEVAS | E13: ANGOL | F13: 102 | G13: 2668980 | H13: 58 | I13: 1517420
A14: 86732041 | B14: ROMAN JUAN CASTRO CAYO | C14: 6 | D14: HECTOR CAFFIERO VASQUEZ | E14: ARICA | F14: 41 | G14: 1029590 | H14: 42 | I14: 1057580
A15: 8780898K | B15: PATRICIA HAFON DESMOND | C15: 6 | D15: HECTOR CAFFIERO VASQUEZ | E15: TOCOPILLA | F15: 8 | G15: 207920 | H15: 0 | I15: 0
A16: 92761525 | B16: CARMEN GLORIA GALLARDO VALERIO | C16: 2 | D16: PATRICIO CUEVAS | E16: LA UNION | F16: 121 | G16: 3165790 | H16: 106 | I16: 2771940
A17: 93052528 | B17: SABINA QUISPE PAIRO | C17: 6 | D17: HECTOR CAFFIERO VASQUEZ | E17: ARICA | F17: 553 | G17: 14187470 | H17: 441 | I17: 11312590
A18: 94411564 | B18: ANA MARIA SANCHEZ LUENGO | C18: 12 | D18: CARLOS CUEVAS | E18: PUREN | F18: 90 | G18: 2316100 | H18: 84 | I18: 2154160
A19: 96234422 | B19: MIRNA PACHECO RABANAL | C19: 2 | D19: PATRICIO CUEVAS | E19: CABRERO | F19: 228 | G19: 5836720 | H19: 198 | I19: 5030020
A20: 102705084 | B20: ELIANA VENTURELLI REGLA | C20: 12 | D20: CARLOS CUEVAS | E20: CAPITAN PASTENE | F20: 190 | G20: 4834100 | H20: 121 | I20: 3051790
A21: 105613059 | B21: MARISOL DURAN NAVARRO | C21: 12 | D21: CARLOS CUEVAS | E21: MELIPILLA | F21: 42 | G21: 1112580 | H21: 41 | I21: 1086590
A22: 10879819K | B22: CELIA VASQUEZ BARRERA | C22: 2 | D22: PATRICIO CUEVAS | E22: VILLARICA | F22: 49 | G22: 1240510 | H22: 40 | I22: 1006600
A23: 114079979 | B23: DANITZA OSSES AEDO | C23: 12 | D23: CARLOS CUEVAS | E23: TRAIGUEN | F23: 106 | G23: 2716940 | H23: 95 | I23: 2438050
A24: 115643592 | B24: BELLA FUENTES PINCHEIRA | C24: 13 | D24: RICHARD CUEVAS | E24: LINARES | F24: 623 | G24: 16052770 | H24: 497 | I24: 12767030
A25: 116841290 | B25: HUGO MONTERO FIGUEROA | C25: 2 | D25: PATRICIO CUEVAS | E25: LOS ANGELES | F25: 397 | G25: 10084030 | H25: 380 | I25: 9639200
A26: 120037366 | B26: ARMANDO BARRIA LEGUE | C26: 3 | D26: SERGIO KRAMARENCO | E26: PUERTO NATALES | F26: 70 | G26: 1772300 | H26: 57 | I26: 1447430
A27: 123737024 | B27: ISVELDA MELO ACEVEDO | C27: 2 | D27: PATRICIO CUEVAS | E27: LINARES | F27: 18 | G27: 467820 | H27: 0 | I27: 0
A28: 12838491K | B28: JESSICA ARAYA CEPEDA | C28: 6 | D28: HECTOR CAFFIERO VASQUEZ | E28: ANTOFAGASTA | F28: 4 | G28: 103960 | H28: 4 | I28: 103960
A29: 136381334 | B29: KAREN HUAMAN LOPEZ | C29: 6 | D29: HECTOR CAFFIERO VASQUEZ | E29: ARICA | F29: 11 | G29: 296890 | H29: 11 | I29: 296890
A30: 137440369 | B30: CARLA ALIAGA | C30: 6 | D30: HECTOR CAFFIERO VASQUEZ | E30: VALLENAR | F30: 192 | G30: 4942080 | H30: 163 | I30: 4191370
A31: 138622045 | B31: PAOLA NAVARRO | C31: 6 | D31: HECTOR CAFFIERO VASQUEZ | E31: ARICA | F31: 48 | G31: 1253520 | H31: 22 | I31: 571780
A32: 139701321 | B32: GLORIA GALINDO PEREZ | C32: 3 | D32: SERGIO KRAMARENCO | E32: COYHAIQUE | F32: 250 | G32: 6409500 | H32: 240 | I32: 6159600
A33: 143849244 | B33: MONICA SANDOVAL NAVARRETE | C33: 2 | D33: PATRICIO CUEVAS | E33: COLLIPULLI | F33: 92 | G33: 2329080 | H33: 92 | I33: 2335080
A34: 144052439 | B34: CECILIA RIVERA ROMERO | C34: 2 | D34: PATRICIO CUEVAS | E34: TEMUCO | F34: 366 | G34: 9408340 | H34: 340 | I34: 8732600
A35: 144967860 | B35: CRISTIAN ALEJANDRO FUENTES FLORES | C35: 12 | D35: CARLOS CUEVAS | E35: RANCAGUA | F35: 359 | G35: 9313410 | H35: 228 | I35: 5950720
A36: 146351107 | B36: CAROLINA MIRANDA | C36: 12 | D36: CARLOS CUEVAS | E36: SANTA CRUZ | F36: 304 | G36: 7886960 | H36: 269 | I36: 6956310
A37: 154536493 | B37: MARITZA TOSSO CATRICURA | C37: 3 | D37: SERGIO KRAMARENCO | E37: PANGUIPULLI | F37: 44 | G37: 1111560 | H37: 20 | I37: 511800
A38: 16065905K | B38: PATRICIA CANALES OYARZUN | C38: 3 | D38: SERGIO KRAMARENCO | E38: PUNTA ARENAS | F38: 216 | G38: 5676840 | H38: 125 | I38: 3276750
A39: 162593110 | B39: KATERIN FRANCHESCA CASANGA SANTANA | C39: 6 | D39: HECTOR CAFFIERO VASQUEZ | E39: CALAMA | F39: 214 | G39: 5603860 | H39: 125 | I39: 3258750
A40: 162603744 | B40: JETZABEL AGUIRRE ALVAREZ | C40: 6 | D40: HECTOR CAFFIERO VASQUEZ | E40: CALAMA | F40: 446 | G40: 11605540 | H40: 396 | I40: 10290040
...

Sheet TRAYECTORIA
A1: CLIENTES DE TRAYECTORIA
A3: N° | B3: CLIENTES | C3: DESCUENTO
A4: 1 | B4: COMERCIAL GERMANI | C4: 0.05
A5: 2 | B5: ESTABLECIMIENTO GERMANI | C5: 0.05
A6: 3 | B6: SEIDEMAN | C6: 0.05
A7: 4 | B7: MULTICENTRO | C7: -
A8: 5 | B8: INV JULIAN | C8: 0.05
A9: 6 | B9: JAVER HNOS | C9: 0.05
A10: 7 | B10: COMERCIAL NACE | C10: 0.05
A11: 8 | B11: ALMACENES ELTIT | C11: 0.05
A12: 9 | B12: DOLLY | C12: 0.05
A13: 10 | B13: ROBERTO KOBUS | C13: 0.05

Sheet DESCUENTO COLE 18
A2: DESCUENTO COLE 18 (10/09/2021) POR PAGO DE CONTADO
B4: N° | C4: CLIENTES | D4: DESCUENTO
B5: 1 | C5: SOC.FLORES ALMANDOZ NA | D5: 0.05
B6: 2 | C6: FORCAEL | D6: 0.05
B7: 3 | C7: DOLLY | D7: 0.05
B8: 4 | C8: ROBERTO KOBUS | D8: 0.05
B9: 5 | C9: DUSAN | D9: 0.05
B10: 6 | C10: HUGO MONTERO | D10: 0.05
B11: 7 | C11: GRAN AVENTURA | D11: 0.05
B12: 8 | C12: SOC. COM. DON JORGE | D12: 0.05
B13: 9 | C13: MIRNA PACHECO | D13: 0.05
B14: 10 | C14: SABINA QUISPE | D14: 0.05
B15: 11 | C15: WILFREDO ROJAS | D15: 0.05
B16: 12 | C16: SOC COMERCIAL CMUA | D16: 0.05
... B37: 33 | C37: BOUTIQUE LA HERRADURA | D37: 0.05

Sheet CONTRAFACTURA
A1: CLIENTES DE TRAYECTORIA
A3: N° | B3: CLIENTES | C3: DESCUENTO
A4: 1 | B4: COMERCIAL GERMANI | C4: 0.05
A5: 2 | B5: ESTABLECIMIENTO GERMANI | C5: 0.05
A6: 3 | B6: SEIDEMAN | C6: 0.05
A7: 4 | B7: MULTICENTRO | C7: -
A8: 5 | B8: INV JULIAN | C8: 0.05
A9: 6 | B9: JAVER HNOS | C9: 0.05
A10: 7 | B10: COMERCIAL NACE | C10: 0.05
A11: 8 | B11: ALMACENES ELTIT | C11: 0.05
A12: 9 | B12: DOLLY | C12: 0.05
A13: 10 | B13: ROBERTO KOBUS | C13: 0.05
