Workbook
Name BB: #REF!
Name CCC: #REF!
Name div: 'BD jeans Dama'!#REF!
Name his: #REF!
Name hist: #REF!
Name JEAN: 'BD jeans Dama'!#REF!
Name jeandama: 'BD jeans Dama'!#REF!
Name jeanss: 'BD jeans Dama'!#REF!
Name jeansss: 'BD jeans Dama'!$A$1:$F$4062
Name jn: 'BD jeans Dama'!#REF!
Name jnss: 'BD jeans Dama'!$A$2:$F$536
Name L: 'BASE DE DATOS OFICIAL'!$A$1:$D$126
Name mahis: #REF!
Name matof: 'BASE DE DATOS OFICIAL'!$A$16:$AF$371
Name matrix: #REF!
Name matrizoficial: 'BASE DE DATOS OFICIAL'!$16:$65452
Name MAX: #REF!
Name MAXX: #REF!
Name PLANILLA: #REF!
Name PLANILLA1: 'BASE DE DATOS OFICIAL'!$A$3:$CU$373
Name PLANILLA2: #REF!
Name PLANILLAMOD: 'BASE DE DATOS OFICIAL'!$A$16:$V$122
Name RUT: #REF!
Name RUTES: #REF!
Name VENTAS: #REF!
Name jeans: 'BD jeans Dama'!$A$1:$F$440
Name jeans2: 'BD jeans Dama'!$B$1:$I$440

Sheet TOMA DE PEDIDOS
E1: TRANSPORTE | H1: RAZON SOCIAL | L1: =_xlfn.IFNA(VLOOKUP(L5,'BASE DE DATOS OFICIAL'!$A$4:$AC$166,3,0),"SIN INFORMACIÓN")
H2: GIRO | L2: =_xlfn.IFNA(VLOOKUP(L5,'BASE DE DATOS OFICIAL'!$A$4:$AC$166,19,0),"SIN INFORMACIÓN")
E3: =VLOOKUP(L5,'BASE DE DATOS OFICIAL'!A3:AC166,14,0) | H3: DIRECCION | L3: =_xlfn.IFNA(VLOOKUP(L5,'BASE DE DATOS OFICIAL'!$A$4:$AC$166,5,0),"SIN INFORMACIÓN")
H4: NOMBRE TIENDA | L4: =_xlfn.IFNA(VLOOKUP(L5,'BASE DE DATOS OFICIAL'!$A$4:$AC$166,20,0),"SIN INFORMACIÓN")
E5: CONDICIONES DE PAGO | H5: RUT | Q5: FECHA
H6: COMUNA | L6: =_xlfn.IFNA(VLOOKUP(L5,'BASE DE DATOS OFICIAL'!$A$4:$AC$166,21,0),"SIN INFORMACIÓN") | Q6: CIUDAD | S6: =_xlfn.IFNA(VLOOKUP(L5,'BASE DE DATOS OFICIAL'!$A$4:$AC$166,4,0),"SIN INFORMACIÓN")
C7: MANUFACTURAS e IMPORTACIONES | E7: =_xlfn.IFNA(VLOOKUP(L5,'BASE DE DATOS OFICIAL'!$A$4:$AC$166,17,0),"SIN INFORMACIÓN") | H7: TELEFONO | L7: =_xlfn.IFNA(VLOOKUP(L5,'BASE DE DATOS OFICIAL'!$A$4:$AC$166,6,0),"SIN INFORMACIÓN") | Q7: CELULAR | S7: =_xlfn.IFNA(VLOOKUP(L5,'BASE DE DATOS OFICIAL'!$A$4:$AC$166,18,0),"SIN INFORMACIÓN")
C8: TITANIUM CHILE SPA | H8: ATENCION | L8: =TODAY() | Q8: E-MAIL | S8: =_xlfn.IFNA(VLOOKUP(L5,'BASE DE DATOS OFICIAL'!$A$4:$AC$166,9,0),"SIN INFORMACIÓN")
E9: NOTA DE PEDIDO | H9: VENDEDOR | L9: =_xlfn.IFNA(VLOOKUP(L5,'BASE DE DATOS OFICIAL'!$A$4:$AC$166,7,0),"SIN INFORMACIÓN") | Q9: ORDEN DE COMPRA | S9: 43 ALTO INVIERNO
C10: Av. Peru 710, Recoleta-Santiago | H10: TEMPORADA | L10: OTOÑO INVIERNO 2026
C11: www.mohicano.cl | E11: 143011 | H11: VENTA SUGERIDA | L11: =_xlfn.IFNA(VLOOKUP(L5,'BASE DE DATOS OFICIAL'!$A$4:$AC$166,29,0),"SIN INFORMACIÓN") | N11: prendas | Q11: DESCUENTO
H12: COLE. ANTERIOR | L12: PEDIDO REALIZADO | Q12: DESPACHO | S12: SALDO | T12: VALOR
H13: 3800 | L13: =_xlfn.IFNA(VLOOKUP(L5,'BASE DE DATOS OFICIAL'!$A$4:$AC$166,24,0),"SIN INFORMACIÓN") | Q13: =_xlfn.IFNA(VLOOKUP(L5,'BASE DE DATOS OFICIAL'!$A$4:$AC$166,25,0),"SIN INFORMACIÓN") | S13: =_xlfn.IFNA(VLOOKUP(L5,'BASE DE DATOS OFICIAL'!$A$4:$AC$166,26,0),"SIN INFORMACIÓN") | T13: =_xlfn.IFNA(VLOOKUP(L5,'BASE DE DATOS OFICIAL'!$A$4:$AC$166,28,0),"SIN INFORMACIÓN")
A14: BARRA | B14: CÓDIGO | C14: ARTÍCULO | D14: TIRO | E14: CORTE | F14: 36 | G14: 38 | H14: 40 | I14: 42 | J14: 44 | K14: 46 | L14: 48 | M14: 50 | N14: S | O14: M | P14: L | Q14: PRENDAS | S14: VALOR | T14: TOTAL
C15: =IF(B15<>"",VLOOKUP(B15,jeans2,2,FALSE),IF(A15<>"",VLOOKUP(A15,jeans,3,FALSE),"")) | D15: =IF(B15<>"",VLOOKUP(B15,jeans2,3,FALSE),IF(A15<>"",VLOOKUP(A15,jeans,4,FALSE),"")) | E15: =IF(B15<>"",VLOOKUP(B15,jeans2,4,FALSE),IF(A15<>"",VLOOKUP(A15,jeans,5,FALSE),"")) | Q15: =SUM($F15:$P15) | S15: =IF(B15<>"",VLOOKUP(B15,jeans2,5,FALSE),IF(A15<>"",VLOOKUP(A15,jeans,6,FALSE),"")) | T15: =IFERROR(Q15*S15,"")
C16: =IF(B16<>"",VLOOKUP(B16,jeans2,2,FALSE),IF(A16<>"",VLOOKUP(A16,jeans,3,FALSE),"")) | D16: =IF(B16<>"",VLOOKUP(B16,jeans2,3,FALSE),IF(A16<>"",VLOOKUP(A16,jeans,4,FALSE),"")) | E16: =IF(B16<>"",VLOOKUP(B16,jeans2,4,FALSE),IF(A16<>"",VLOOKUP(A16,jeans,5,FALSE),"")) | Q16: =SUM($F16:$P16) | S16: =IF(B16<>"",VLOOKUP(B16,jeans2,5,FALSE),IF(A16<>"",VLOOKUP(A16,jeans,6,FALSE),"")) | T16: =IFERROR(Q16*S16,"")
C17: =IF(B17<>"",VLOOKUP(B17,jeans2,2,FALSE),IF(A17<>"",VLOOKUP(A17,jeans,3,FALSE),"")) | D17: =IF(B17<>"",VLOOKUP(B17,jeans2,3,FALSE),IF(A17<>"",VLOOKUP(A17,jeans,4,FALSE),"")) | E17: =IF(B17<>"",VLOOKUP(B17,jeans2,4,FALSE),IF(A17<>"",VLOOKUP(A17,jeans,5,FALSE),"")) | Q17: =SUM($F17:$P17) | S17: =IF(B17<>"",VLOOKUP(B17,jeans2,5,FALSE),IF(A17<>"",VLOOKUP(A17,jeans,6,FALSE),"")) | T17: =IFERROR(Q17*S17,"")
C18: =IF(B18<>"",VLOOKUP(B18,jeans2,2,FALSE),IF(A18<>"",VLOOKUP(A18,jeans,3,FALSE),"")) | D18: =IF(B18<>"",VLOOKUP(B18,jeans2,3,FALSE),IF(A18<>"",VLOOKUP(A18,jeans,4,FALSE),"")) | E18: =IF(B18<>"",VLOOKUP(B18,jeans2,4,FALSE),IF(A18<>"",VLOOKUP(A18,jeans,5,FALSE),"")) | Q18: =SUM($F18:$P18) | S18: =IF(B18<>"",VLOOKUP(B18,jeans2,5,FALSE),IF(A18<>"",VLOOKUP(A18,jeans,6,FALSE),"")) | T18: =IFERROR(Q18*S18,"")
C19: =IF(B19<>"",VLOOKUP(B19,jeans2,2,FALSE),IF(A19<>"",VLOOKUP(A19,jeans,3,FALSE),"")) | D19: =IF(B19<>"",VLOOKUP(B19,jeans2,3,FALSE),IF(A19<>"",VLOOKUP(A19,jeans,4,FALSE),"")) | E19: =IF(B19<>"",VLOOKUP(B19,jeans2,4,FALSE),IF(A19<>"",VLOOKUP(A19,jeans,5,FALSE),"")) | Q19: =SUM($F19:$P19) | S19: =IF(B19<>"",VLOOKUP(B19,jeans2,5,FALSE),IF(A19<>"",VLOOKUP(A19,jeans,6,FALSE),"")) | T19: =IFERROR(Q19*S19,"")
C20: =IF(B20<>"",VLOOKUP(B20,jeans2,2,FALSE),IF(A20<>"",VLOOKUP(A20,jeans,3,FALSE),"")) | D20: =IF(B20<>"",VLOOKUP(B20,jeans2,3,FALSE),IF(A20<>"",VLOOKUP(A20,jeans,4,FALSE),"")) | E20: =IF(B20<>"",VLOOKUP(B20,jeans2,4,FALSE),IF(A20<>"",VLOOKUP(A20,jeans,5,FALSE),"")) | Q20: =SUM($F20:$P20) | S20: =IF(B20<>"",VLOOKUP(B20,jeans2,5,FALSE),IF(A20<>"",VLOOKUP(A20,jeans,6,FALSE),"")) | T20: =IFERROR(Q20*S20,"")
C21: =IF(B21<>"",VLOOKUP(B21,jeans2,2,FALSE),IF(A21<>"",VLOOKUP(A21,jeans,3,FALSE),"")) | D21: =IF(B21<>"",VLOOKUP(B21,jeans2,3,FALSE),IF(A21<>"",VLOOKUP(A21,jeans,4,FALSE),"")) | E21: =IF(B21<>"",VLOOKUP(B21,jeans2,4,FALSE),IF(A21<>"",VLOOKUP(A21,jeans,5,FALSE),"")) | Q21: =SUM($F21:$P21) | S21: =IF(B21<>"",VLOOKUP(B21,jeans2,5,FALSE),IF(A21<>"",VLOOKUP(A21,jeans,6,FALSE),"")) | T21: =IFERROR(Q21*S21,"")
C22: =IF(B22<>"",VLOOKUP(B22,jeans2,2,FALSE),IF(A22<>"",VLOOKUP(A22,jeans,3,FALSE),"")) | D22: =IF(B22<>"",VLOOKUP(B22,jeans2,3,FALSE),IF(A22<>"",VLOOKUP(A22,jeans,4,FALSE),"")) | E22: =IF(B22<>"",VLOOKUP(B22,jeans2,4,FALSE),IF(A22<>"",VLOOKUP(A22,jeans,5,FALSE),"")) | Q22: =SUM($F22:$P22) | S22: =IF(B22<>"",VLOOKUP(B22,jeans2,5,FALSE),IF(A22<>"",VLOOKUP(A22,jeans,6,FALSE),"")) | T22: =IFERROR(Q22*S22,"")
C23: =IF(B23<>"",VLOOKUP(B23,jeans2,2,FALSE),IF(A23<>"",VLOOKUP(A23,jeans,3,FALSE),"")) | D23: =IF(B23<>"",VLOOKUP(B23,jeans2,3,FALSE),IF(A23<>"",VLOOKUP(A23,jeans,4,FALSE),"")) | E23: =IF(B23<>"",VLOOKUP(B23,jeans2,4,FALSE),IF(A23<>"",VLOOKUP(A23,jeans,5,FALSE),"")) | Q23: =SUM($F23:$P23) | S23: =IF(B23<>"",VLOOKUP(B23,jeans2,5,FALSE),IF(A23<>"",VLOOKUP(A23,jeans,6,FALSE),"")) | T23: =IFERROR(Q23*S23,"")
C24: =IF(B24<>"",VLOOKUP(B24,jeans2,2,FALSE),IF(A24<>"",VLOOKUP(A24,jeans,3,FALSE),"")) | D24: =IF(B24<>"",VLOOKUP(B24,jeans2,3,FALSE),IF(A24<>"",VLOOKUP(A24,jeans,4,FALSE),"")) | E24: =IF(B24<>"",VLOOKUP(B24,jeans2,4,FALSE),IF(A24<>"",VLOOKUP(A24,jeans,5,FALSE),"")) | Q24: =SUM($F24:$P24) | S24: =IF(B24<>"",VLOOKUP(B24,jeans2,5,FALSE),IF(A24<>"",VLOOKUP(A24,jeans,6,FALSE),"")) | T24: =IFERROR(Q24*S24,"")
C25: =IF(B25<>"",VLOOKUP(B25,jeans2,2,FALSE),IF(A25<>"",VLOOKUP(A25,jeans,3,FALSE),"")) | D25: =IF(B25<>"",VLOOKUP(B25,jeans2,3,FALSE),IF(A25<>"",VLOOKUP(A25,jeans,4,FALSE),"")) | E25: =IF(B25<>"",VLOOKUP(B25,jeans2,4,FALSE),IF(A25<>"",VLOOKUP(A25,jeans,5,FALSE),"")) | Q25: =SUM($F25:$P25) | S25: =IF(B25<>"",VLOOKUP(B25,jeans2,5,FALSE),IF(A25<>"",VLOOKUP(A25,jeans,6,FALSE),"")) | T25: =IFERROR(Q25*S25,"")
C26: =IF(B26<>"",VLOOKUP(B26,jeans2,2,FALSE),IF(A26<>"",VLOOKUP(A26,jeans,3,FALSE),"")) | D26: =IF(B26<>"",VLOOKUP(B26,jeans2,3,FALSE),IF(A26<>"",VLOOKUP(A26,jeans,4,FALSE),"")) | E26: =IF(B26<>"",VLOOKUP(B26,jeans2,4,FALSE),IF(A26<>"",VLOOKUP(A26,jeans,5,FALSE),"")) | Q26: =SUM($F26:$P26) | S26: =IF(B26<>"",VLOOKUP(B26,jeans2,5,FALSE),IF(A26<>"",VLOOKUP(A26,jeans,6,FALSE),"")) | T26: =IFERROR(Q26*S26,"")
... C59: =IF(B59<>"",VLOOKUP(B59,jeans2,2,FALSE),IF(A59<>"",VLOOKUP(A59,jeans,3,FALSE),"")) | D59: =IF(B59<>"",VLOOKUP(B59,jeans2,3,FALSE),IF(A59<>"",VLOOKUP(A59,jeans,4,FALSE),"")) | E59: =IF(B59<>"",VLOOKUP(B59,jeans2,4,FALSE),IF(A59<>"",VLOOKUP(A59,jeans,5,FALSE),"")) | Q59: =SUM($F59:$P59) | S59: =IF(B59<>"",VLOOKUP(B59,jeans2,5,FALSE),IF(A59<>"",VLOOKUP(A59,jeans,6,FALSE),"")) | T59: =IFERROR(Q59*S59,"")
C60: =IF(B60<>"",VLOOKUP(B60,jeans2,2,FALSE),IF(A60<>"",VLOOKUP(A60,jeans,3,FALSE),"")) | D60: =IF(B60<>"",VLOOKUP(B60,jeans2,3,FALSE),IF(A60<>"",VLOOKUP(A60,jeans,4,FALSE),"")) | E60: =IF(B60<>"",VLOOKUP(B60,jeans2,4,FALSE),IF(A60<>"",VLOOKUP(A60,jeans,5,FALSE),"")) | F60: CANTIDAD TOTAL DE ARTICULOS | Q60: =SUM(Q15:Q59) | S60: =IF(B60<>"",VLOOKUP(B60,jeans2,5,FALSE),IF(A60<>"",VLOOKUP(A60,jeans,6,FALSE),"")) | T60: =IFERROR(Q60*S60,"")
B61: OBSERVACIONES | R61: Descuento especial: | S61: 0 | T61: =+T60*S61
S62: NETO | T62: =+T60-T61
B63: Autorizo para comunicar a terceros la mora o simple retardo de la obligación, en la base de datos SICOM | S63: IVA 19% | T63: =T62*19%
B64: (Sistema consolidado de morosidad y protesto) de DICOM S.A. o en cualquier otra base de datos de morosidades y protestos existentes | S64: TOTAL | T64: =T62+T63

Sheet Stock
A1: CODIGO | B1: TIRO | C1: BOTA | D1: COLOR | E1: 36 | F1: 38 | G1: 40 | H1: 42 | I1: 44 | J1: 46 | L1: CODIGO | M1: TIRO | N1: BOTA | O1: COLOR | P1: 36 | Q1: 38 | R1: 40 | S1: 42 | T1: 44 | U1: 46
A2: 423600 | B2: CINTURA | C2: PALAZZO | E2: 24 | F2: 46 | G2: 42 | H2: 41 | I2: 32 | J2: 25 | L2: 432900 | M2: MEDIO | N2: OXFORD | P2: 50 | Q2: 118 | R2: 125 | S2: 116 | T2: 83 | U2: 68
A3: 422200 | B3: MEDIO | C3: TOBILLERO | E3: 13 | F3: 60 | G3: 53 | H3: 48 | I3: 31 | L3: 431800 | M3: CINTURA | N3: WIDE | P3: 56 | Q3: 117 | R3: 127 | S3: 98 | T3: 79 | U3: 54
A4: 423500 | B4: CINTURA | C4: PITILLO | E4: 8 | F4: 31 | G4: 31 | H4: 31 | I4: 26 | J4: 11 | L4: 430900 | M4: CINTURA | N4: FLARE | P4: 18 | Q4: 51 | R4: 55 | S4: 48 | T4: 35 | U4: 26
A5: 420301 | B5: MEDIO | C5: TOBILLERO | E5: 7 | F5: 24 | G5: 27 | H5: 29 | I5: 14 | J5: 4 | L5: 432300 | M5: CINTURA | N5: WIDE LEG | P5: 56 | Q5: 115 | R5: 132 | S5: 122 | T5: 85 | U5: 66
A6: 420600 | B6: CINTURA | C6: PITILLO | E6: 24 | F6: 3 | H6: 10 | I6: 18 | J6: 8
A7: 420100 | B7: CINTURA | C7: PITILLO | E7: 27 | F7: 22 | G7: 52 | H7: 12 | I7: 8
A8: 424400 | B8: CINTURA | C8: PITILLO | E8: 27 | F8: 27 | G8: 24 | H8: 32
A9: 422300 | B9: MEDIO | C9: FLARE | E9: 18 | F9: 19 | G9: 11 | H9: 19 | I9: 16
A10: 420300 | B10: MEDIO | C10: TOBILLERO | E10: 13 | F10: 15 | G10: 16 | H10: 15 | I10: 11 | J10: 10
A11: 420400 | B11: MEDIO | C11: FLARE | E11: 26 | F11: 6 | G11: 9 | H11: 7 | I11: 8 | J11: 16
A12: 423200 | B12: CINTURA | C12: OXFORD | E12: 13 | F12: 1 | G12: 17 | H12: 14 | I12: 12 | J12: 14
A13: 422500 | B13: CINTURA | C13: FLARE | E13: 8 | G13: 12 | H13: 15 | I13: 13 | J13: 17
A14: 424600 | B14: CINTURA | C14: TOBILLERO | E14: 4 | F14: 4 | G14: 22 | H14: 17 | I14: 17
A15: 422800 | B15: MEDIO | C15: FLARE | F15: 4 | G15: 29 | I15: 28
A16: 422000 | B16: CINTURA | C16: PITILLO | E16: 34 | F16: 10 | G16: 11 | H16: 3 | I16: 3
A17: 423316 | B17: CINTURA | C17: TOBILLERO | E17: 6 | F17: 14 | G17: 14 | H17: 13 | I17: 8 | J17: 4
A18: 422101 | B18: CINTURA | C18: PITILLO | E18: 14 | F18: 1 | G18: 15 | H18: 9 | I18: 14
A19: 421400 | B19: CINTURA | C19: OXFORD | E19: 7 | F19: 0 | G19: 1 | H19: 1 | I19: 12 | J19: 32
A20: 420800 | B20: CINTURA | C20: FLARE | E20: 6 | F20: 10 | G20: 12 | H20: 12 | I20: 6 | J20: 6
A21: 421801 | B21: CINTURA | C21: FLARE | G21: 2 | H21: 3 | I21: 13 | J21: 10
A22: 420160 | B22: CINTURA | C22: PITILLO | D22: CLARO | E22: 7 | F22: 12 | G22: 9 | H22: 10 | I22: 6 | J22: 5
A23: 421100 | B23: CINTURA | C23: FLARE | E23: 3 | F23: 4 | G23: 6 | H23: 6 | I23: 20 | J23: 7
A24: 422700 | B24: CINTURA | C24: RECTO | E24: 10 | F24: 14 | G24: 6 | I24: 6 | J24: 10
A25: 423000 | B25: CINTURA | C25: PALAZZO | E25: 10 | H25: 4 | I25: 21 | J25: 9
A26: 424900 | B26: CINTURA | C26: PALAZZO | D26: negro | E26: 4 | F26: 12 | G26: 13 | H26: 6 | I26: 3 | J26: 0
A27: 424900 | B27: CINTURA | C27: PALAZZO | D27: GRIS | E27: 9 | F27: 14 | G27: 15 | H27: 6 | I27: 4 | J27: 4
A28: 421000 | B28: MEDIO | C28: OXFORD | E28: 5 | F28: 15 | G28: 17 | H28: 16 | I28: 11 | J28: 12
A29: 424000 | B29: CINTURA | C29: PITILLO | E29: 20 | G29: 3 | I29: 10
A30: 422701 | B30: CINTURA | C30: RECTO | E30: 1 | H30: 4 | I30: 11 | J30: 14
A31: 423448 | B31: CINTURA | C31: FLARE | I31: 4
A32: 420101 | B32: CINTURA | C32: PITILLO | E32: 7 | F32: 7 | G32: 7 | H32: 7 | J32: 2
A33: 424701 | B33: CINTURA | C33: RECTO | E33: 2 | G33: 13 | I33: 13
A34: 421901 | B34: CINTURA | C34: PITILLO | E34: 4 | F34: 8 | G34: 6 | H34: 5 | I34: 4 | J34: 1
A35: 422900 | B35: CINTURA | C35: PITILLO | E35: 23 | F35: 1 | I35: 2
A36: 421902 | B36: CINTURA | C36: PITILLO | E36: 2 | F36: 6 | G36: 6 | H36: 5 | I36: 4 | J36: 2
A37: 420501 | B37: CINTURA | C37: OXFORD | E37: 4 | F37: 1 | G37: 5 | H37: 1 | I37: 6 | J37: 4
A38: 422190 | B38: CINTURA | C38: TOBILLERO | D38: GLITEE | E38: 2 | F38: 5 | G38: 5 | H38: 5 | I38: 3 | J38: 3
A39: 421900 | B39: CINTURA | C39: PITILLO | E39: 0 | F39: 4 | G39: 7 | H39: 3 | I39: 8
A40: 423501 | B40: CINTURA | C40: PITILLO | E40: 2 | F40: 6 | G40: 1 | H40: 6 | I40: 2 | J40: 6
...

Sheet Hoja2

Sheet Hoja1

Sheet BD jeans Dama
A1: ARTICULO | B1: CODIGO | C1: DESCRIPCIÓN | D1: TIRO | E1: BOTA | F1: PRECIO
A2: 3801 | B2: 3801 | C2: Pretina revés, doble bolsillo relojero, cierre bota | D2: Cintura | E2: Tobillero | F2: 24990
A3: 3802 | B3: 3802 | C3: Smart Denim pinza costado sin basta | D3: Cintura | E3: Oxford | F3: 25990
A4: 3818 | B4: 3818 | C4: Marengo con roturas láser | D4: Cintura | E4: Recto | F4: 24990
A5: 3821-00 | B5: 3821-00 | C5: Imprentado biodesgastado | D5: Medio | E5: Oxford | F5: 24990
A6: 3821-01 | B6: 3821-01 | C6: Bolsillo delantero, costura ancha, Imprentado ox. | D6: Medio | E6: Oxford | F6: 24990
A7: 3826 | B7: 3826 | C7: Vestido negro con cinturón | D7: Vestido | E7: Muslo | F7: 28990
A8: 3832-09 | B8: 3832-09 | C8: Verde con pretina desflecada | D8: Cintura | E8: Palazzo | F8: 26990
A9: 3834 | B9: 3834 | C9: Clásico 5 bolsillos, gris con repaso costura | D9: Cintura | E9: Palazzo | F9: 26990
A10: 3837 | B10: 3837 | C10: Cargo negro Eco Cuero | D10: Cintura | E10: Recto | F10: 26990
A11: 3840 | B11: 3840 | C11: Clásico gris gravillado, bolsillos traseros curvos | D11: Cintura | E11: Flare | F11: 25990
A12: 3846-04 | B12: 3846-04 | C12: Cargo 4 bolsillos color chocolate | D12: Medio | E12: Palazzo | F12: 26990
A13: 3846-06 | B13: 3846-06 | C13: Cargo 4 bolsillos teñido orgánico con nueces | D13: Medio | E13: Palazzo | F13: 26990
A14: 3846-09 | B14: 3846-09 | C14: Cargo 4 bolsillos color Verde Oliva | D14: Medio | E14: Palazzo | F14: 26990
A15: 3846-38 | B15: 3846-38 | C15: Cargo 4 bolsillos color Ostra | D15: Medio | E15: Palazzo | F15: 26990
A16: 3846-71 | B16: 3846-71 | C16: Cargo 4 bolsillos color Terracota | D16: Medio | E16: Palazzo | F16: 26990
A17: 3849 | B17: 3849 | C17: Clásico | D17: Cintura | E17: Pitillo | F17: 24990
A18: 3853-04 | B18: 3853-04 | C18: Cargo/cinturón chocolate hilo al tono | D18: Cintura | E18: Oxford | F18: 26990
A19: 3851 | B19: 3851 | C19: Pieza lateral | D19: Cintura | E19: Palazzo | F19: 26990
A20: 3857 | B20: 3857 | C20: Azúl focalizado tenue, pinzas delanteras y traseras | D20: Cintura | E20: Pitillo | F20: 24990
A21: 3858 | B21: 3858 | C21: Wide Leg marengo | D21: Cintura | E21: Recto/ Cargo | F21: 26990
A22: 3859 | B22: 3859 | C22: Casaca oversize, bordado, gravillado | D22: Casaca | F22: 25990
A23: 3860 | B23: 3860 | C23: Corte diagonal en pretina | D23: Medio | E23: Tobillero | F23: 24990
A24: 3861 | B24: 3861 | C24: HIGH WAIST sin pinza | D24: Cintura | E24: Recto | F24: 24990
A25: 3862-00 | B25: 3862-00 | C25: Clásico color negro bolsillos traseros ovalados | D25: Medio | E25: Recto | F25: 24990
A26: 3862-01 | B26: 3862-01 | C26: Clásico Gris focalizado bolsillos traseros ovalados | D26: Medio | E26: Recto | F26: 24990
A27: 3865 | B27: 3865 | C27: Push in push up azúl focalizado | D27: Cintura | E27: Flare | F27: 25990
A28: 3869 | B28: 3869 | C28: Negro pestaña bolsillo delantero | D28: Cintura | E28: Flare | F28: 25990
A29: 3870 | B29: 3870 | C29: Casaca oversize con tapetas, gravillado | D29: Casaca | F29: 26990
A30: 3871-00 | B30: 3871-00 | C30: Pretina ancha con doble botón Bio Medio | D30: Cintura | E30: Pitillo | F30: 24990
A31: 3871-01 | B31: 3871-01 | C31: Pretina ancha c/doble botón, focalizado oxidado | D31: Cintura | E31: Pitillo | F31: 24990
A32: 3877 | B32: 3877 | C32: Negro con aplicación Lumen | D32: Cintura | E32: Pitillo | F32: 24990
A33: 3878 | B33: 3878 | C33: Pretina desflecada sin basta desflecada | D33: Cintura | E33: Palazzo | F33: 26990
A34: 3879 | B34: 3879 | C34: Tajali en bota, pieza en altura bigotes | D34: Medio | E34: Tobillero | F34: 24990
A35: 3880 | B35: 3880 | C35: Smart Denim roturas delanteras | D35: Cintura | E35: Tobillero | F35: 24990
A36: 3882-00 | B36: 3882-00 | C36: Marengo gravillado 2 pasadores, pinza lateral | D36: Cintura | E36: Recto | F36: 24990
A37: 3882-01 | B37: 3882-01 | C37: Negro 2 pasadores, pinza lateral | D37: Cintura | E37: Recto | F37: 24990
A38: 3883 | B38: 3883 | C38: Clásico 5 bolsillos bolsillo trasero destroyed | D38: Cintura | E38: Recto | F38: 24990
A39: 3886 | B39: 3886 | C39: Wide Leg azúl focalizado tenue | D39: Cintura | E39: Palazzo | F39: 26990
A40: 3888 | B40: 3888 | C40: Cargo azúl, con bolsillos carpinteros | D40: Cintura | E40: Recto | F40: 26990
...

Sheet Cálculo Intereses
A1: RUT | C1: Nombre
A3: Capital adeudado | B3: 8000000
A5: Pié | B5: 5000000
A6: Cuotas | B6: 6
A7: Interés | B7: 0.02
A8: Inicio de fecha | B8: 46183
A9: Valor Intereses | B9: =(($B$3-$B$5)*$B$7)*$B$6
A11: Cuota | B11: Fecha | C11: Valor
A12: =($B$6)-($B$6-1) | B12: =+B8 | C12: =IF(A12<>"-",(($B$3-$B$5)/10+($B$9/$B$6)),"-")
A13: =IF($B$6=2,"2",IF($B$6<2,"-","2")) | B13: =IF(A13<>"-",B12+30,"-") | C13: =IF(A13<>"-",(($B$3-$B$5)/10+($B$9/$B$6)),"-")
A14: =IF($B$6=3,"3",IF($B$6<3,"-","3")) | B14: =IF(A14<>"-",B13+30,"-") | C14: =IF(A14<>"-",(($B$3-$B$5)/10+($B$9/$B$6)),"-")
A15: =IF($B$6=4,"4",IF($B$6<4,"-","4")) | B15: =IF(A15<>"-",B14+30,"-") | C15: =IF(A15<>"-",(($B$3-$B$5)/10+($B$9/$B$6)),"-")
A16: =IF($B$6=5,"5",IF($B$6<5,"-","5")) | B16: =IF(A16<>"-",B15+30,"-") | C16: =IF(A16<>"-",(($B$3-$B$5)/10+($B$9/$B$6)),"-")
A17: =IF($B$6=6,"6",IF($B$6<6,"-","6")) | B17: =IF(A17<>"-",B16+30,"-") | C17: =IF(A17<>"-",(($B$3-$B$5)/10+($B$9/$B$6)),"-")
A18: =IF($B$6=7,"7",IF($B$6<7,"-","7")) | B18: =IF(A18<>"-",B17+30,"-") | C18: =IF(A18<>"-",(($B$3-$B$5)/10+($B$9/$B$6)),"-")
A19: =IF($B$6=8,"8",IF($B$6<8,"-","8")) | B19: =IF(A19<>"-",B18+30,"-") | C19: =IF(A19<>"-",(($B$3-$B$5)/10+($B$9/$B$6)),"-")
A20: =IF($B$6=9,"9",IF($B$6<9,"-","9")) | B20: =IF(A20<>"-",B19+30,"-") | C20: =IF(A20<>"-",(($B$3-$B$5)/10+($B$9/$B$6)),"-")
A21: =IF($B$6=10,"10",IF($B$6<10,"-","10")) | B21: =IF(A21<>"-",B20+30,"-") | C21: =IF(A21<>"-",(($B$3-$B$5)/10+($B$9/$B$6)),"-")
C22: =SUM(C12:C21)

Sheet Hoja3
A1: 436500 | B1: Jeans Cintura recto, Smart Denim, doble pasador delantero. | C1: Cintura | D1: Recto | E1: 25990 | F1: 3902
A2: 436204 | B2: Jeans Cintura Pitillo colores, Clásico, pasador alto CAFÉ | C2: Cintura | D2: Pitillo | E2: 25990 | F2: 4233/ colores | G2: Descargar
A3: 436206 | B3: Jeans Cintura Pitillo colores, Clásico, pasador alto BEIGE | C3: Cintura | D3: Pitillo | E3: 25990
A4: 436208 | B4: Jeans Cintura Pitillo colores, Clásico, pasador alto ÓCRE | C4: Cintura | D4: Pitillo | E4: 25990
A5: 436216 | B5: Jeans Cintura Pitillo colores, Clásico, pasador alto VERDE OLIVA | C5: Cintura | D5: Pitillo | E5: 25990
A6: 436248 | B6: Jeans Cintura Pitillo colores, Clásico, pasador alto BURDEO | C6: Cintura | D6: Pitillo | E6: 25991
A7: 436104 | B7: Jeans Cintura Flare, relojero en pretina, pasador trasero en V, CAFÉ | C7: Cintura | D7: Flare | E7: 26990 | F7: EX 4234/ 5 colores | G7: En escritorio
A8: 436106 | B8: Jeans Cintura Flare, relojero en pretina, pasador trasero en V, BEIGE | C8: Cintura | D8: Flare | E8: 26990
A9: 436108 | B9: Jeans Cintura Flare, relojero en pretina, pasador trasero en V, ÓCRE | C9: Cintura | D9: Flare | E9: 26990
A10: 436116 | B10: Jeans Cintura Flare, relojero en pretina, pasador trasero en V, VERDE OLIVA | C10: Cintura | D10: Flare | E10: 26990
A11: 436148 | B11: Jeans Cintura Flare, relojero en pretina, pasador trasero en V, BURDEO | C11: Cintura | D11: Flare | E11: 26990
A12: 437700 | B12: Jeans Cintura Palazzo, gris Acero | C12: Cintura | D12: PALAZZO | E12: 26990 | F12: EX 4249
A13: 437900 | B13: Jeans Gris focalizado | C13: Cintura | D13: PALAZZO | E13: 25990 | F13: EX 4003
A14: 437800 | B14: Jeans Cintura Recto, clásico | C14: Cintura | D14: Recto | E14: 25990 | F14: EX 4248
A15: 436600 | B15: Jeans Clásico cintura Recto, bolsillo ovalado, CAFÉ | C15: Cintura | D15: Recto | E15: 25990
A16: 436600 | B16: Jeans Clásico cintura Recto, bolsillo ovalado, BEIGE | C16: Cintura | D16: Recto | E16: 25990
A17: 436600 | B17: Jeans Clásico cintura Recto, bolsillo ovalado, ÓCRE | C17: Cintura | D17: Recto | E17: 25990
A18: 436600 | B18: Jeans Clásico cintura Recto, bolsillo ovalado, VERDE OLIVA | C18: Cintura | D18: Recto | E18: 25990
A19: 436600 | B19: Jeans Clásico cintura Recto, bolsillo ovalado, BURDEO | C19: Cintura | D19: Recto | E19: 25990
A20: 436600 | B20: Jeans Clásico cintura Recto, bolsillo ovalado | C20: Cintura | D20: Recto | E20: 25990

Sheet Respaldo
A1: 1 | B1: 1 | C1: 2 | D1: 3 | E1: 4 | F1: 5 | G1: 6 | H1: 7 | I1: 8 | J1: 9 | K1: 10 | L1: 11 | M1: 12 | N1: 13 | O1: 14 | P1: 15 | Q1: 16 | R1: 17 | S1: 18 | T1: 19 | U1: 20 | V1: 21 | W1: 22 | X1: 23 | Y1: 24 | Z1: 25 | AA1: 26 | AB1: 27 | AC1: 28
A3: RUT | B3: RUT2 | C3: Razon Social | D3: Ciudad | E3: Direccion | F3: Fono | G3: Vendedor | H3: Correo | I3: WWW | J3: Contacto | K3: Cargo | L3: GRUPO | M3: Credito | N3: Transporte | O3: BLOQUEADO | P3: Dcto | Q3: CONDICION DE PAGO | R3: CELULAR | S3: GIRO | T3: NOMBRE DE TIENDA | U3: COMUNA | V3: Observaciones | W3: Ped_anterior | X3: Cantidad | Y3: Despacho | Z3: Saldo | AA3: % Despacho | AB3: Valor | AC3: Meta Cole-38
A4: 4.878.758-4 | B4: 48787584 | C4: ROBERTO KOBUS PEMSO | D4: ANCUD | E4: PUDETO 143-145 | F4: 998269854 | G4: PATRICIO CUEVAS | H4: tiendasmachos@gmail.com | I4: MACHOS BOUTIQUE@SURNET.CL | J4: JENIFER PAGOS | L4: 4 | M4: 0 | N4: VARMONTT | Q4: CREDITO 30 Y 60 | S4: GRANDES TIENDAS | T4: MACHOS | U4: ANCUD | V4: VARMONTT | X4: 487 | Y4: 432 | Z4: 55 | AA4: 0.88706366 | AB4: 12047130 | AC4: 782
A5: 5.001.562-9 | B5: 50015629 | C5: INES VARGAS PINO | D5: COPIAPO | E5: ATACAMA 461-A | F5: 52-213939 | G5: HECTOR CAFFIERO | J5: INES VARGAS | L5: 3 | M5: 0 | N5: SER VALL | P5: 0.05 | Q5: TRANSF. CONTRA FACTURA | R5: 8-8637797 | S5: TIENDA DE VESTIR | T5: BOUTIQUE GEMINIS | U5: COPIAPO | X5: 0 | Y5: 0 | Z5: 0 | AA5: 0 | AB5: 0 | AC5: 0
A6: 5.384.900-8 | B6: 53849008 | C6: ELIANA RIQUELME R. | D6: FUTRONO | E6: BALMACEDA 249 | F6: 966322618 | G6: PATRICIO CUEVAS | J6: ELIANA RIQUELME | L6: 4 | M6: 0 | N6: TUR BUS | Q6: CREDITO 30 Y 60 | S6: VENTAS | T6: COSAS BOUTIQUE | U6: FUTRONO | X6: 0 | Y6: 0 | Z6: 0 | AA6: 0 | AB6: 0 | AC6: 0
A7: 5.913.365-9 | B7: 59133659 | C7: ANA MARIA MANFREDI CARRASCO | D7: OVALLE | E7: VICUÑA MACKENNA 287 | F7: 053-622626 | G7: HECTOR CAFFIERO | H7: manfredi@hotmail.com | J7: DANIELA O ANA MARIA | K7: DUEÑO | L7: 3 | M7: 0 | N7: CHILE LINDO | Q7: CREDITO 30 Y 60 | S7: VENTAS AL POR MENOR | T7: BOUTIQUE PARA TI | U7: =D7 | X7: 182 | Y7: 116 | Z7: 66 | AA7: 0.63736264 | AB7: 4477180 | AC7: 186.3
A8: 6.031.123-4 | B8: 60311234 | C8: FABIOLA BENAVENTE MEZA | D8: PARRAL | E8: ANIBAL PINTO 590 | F8: 961895384 | G8: CARLOS CUEVAS | H8: tiendaelegance@gmail.com | J8: FABIOLA BENAVENTE | K8: POP DESPACHADO 11/12 | L8: 3 | M8: 0 | N8: VILLA PRAT | Q8: CONTRAFACTURA | S8: BOUTIQUE | T8: ELEGANTE BOUTIQUE | U8: PARRAL | X8: 90 | Y8: 88 | Z8: 2 | AA8: 0.97777778 | AB8: 2223100 | AC8: 51.75
A9: 6.331.910-4 | B9: 63319104 | C9: LUIS SOUMASTRE RAMIREZ | D9: ARICA | E9: 21 DE MAYO 454 | F9: 058-2232959 | G9: HECTOR CAFFIERO | H9: lfsr24@hotmail.com | J9: gloria tapia | L9: 3 | M9: 0 | N9: CHACON | Q9: CREDITO 30 Y 60 | S9: VENTAS AL POR MENOR | U9: ARICA | X9: 0 | Y9: 0 | Z9: 0 | AA9: 0 | AB9: 0 | AC9: 26.45
A10: 6.589.904-3 | B10: 65899043 | C10: ANITA BERTA GADICKE | D10: OSORNO | E10: OHIGGINS 534 | F10: 985067217 | G10: PATRICIO CUEVAS | H10: anitagadicke@gmail.com | J10: ANITA GADICKE | L10: 4 | M10: 0 | N10: CIDHER | Q10: CREDITO 30 Y 60 | S10: BOUTIQUE | T10: ALBANY SPORT | U10: OSORNO | X10: 0 | Y10: 0 | Z10: 0 | AA10: 0 | AB10: 0 | AC10: 0
A11: 6.775.324-0 | B11: 67753240 | C11: MARIA DE LOS ANGELES DIAZ BELLIDO | D11: VILLA ALEMANA | E11: BUENOS AIRE 845 | F11: 32-2951011 | G11: PATRICIO CUEVAS | H11: balaustros2@hotmail.com | I11: BALASUTROSVILLAALEMANA@GMAIL.C | J11: MARIA DE LOS ANGELES | L11: 4 | N11: ABC | Q11: CREDITO 30 Y 60 | S11: BOUTIQUE | T11: BALAUSTROS BOUTIQUE | U11: VILLA ALEMANA | X11: 0 | Y11: 0 | Z11: 0 | AA11: 0 | AB11: 0 | AC11: 0
A12: 6.799.967-3 | B12: 67999673 | C12: ANA MARIA SALVATIERRA TAPIA | D12: CABILDO | E12: HUMERES 727 | F12: 91286053 | G12: CARLOS CUEVAS | H12: anisalta@hotmail.com | J12: ANA MARIA SALVATIERR | L12: 3 | M12: 0 | N12: TUR BUS | Q12: CREDITO 30 Y 60 | S12: BOUTIQUE | T12: BOUTIQUE ANITA | U12: CABILDO | X12: 180 | Y12: 176 | Z12: 4 | AA12: 0.97777778 | AB12: 4426200 | AC12: 216.2
A13: 76.965.431-3 | B13: 769654313 | C13: OPALO VESTUARIO | D13: CONCEPCION | E13: BARROS ARANA 815 LOCAL 14 | F13: 991959818 | G13: PATRICIO CUEVAS | H13: mayobenites@hotmail.com | J13: HILIA CONCHA | K13: DUEÑA | L13: 1 | M13: 0 | N13: CHEVALIER | Q13: CHEQUE 30 DIAS | R13: 99594046 | S13: BOUTIQUE | T13: OPALO BOUTIQUE | U13: CONCEPCION | V13: HIJA MARJORIE BENITEZ, TRANSPORTE CHEVALIER 13/11 | X13: 958 | Y13: 678 | Z13: 280 | AA13: 0.70772443 | AB13: 23822420 | AC13: 635.95
A14: 7.096.837-1 | B14: 70968371 | C14: GLORIA CECILIA OLIVARES TORRES | D14: CHAÑARAL | E14: MERINO JARPA 590 | F14: 09-98175762 | G14: HECTOR CAFFIERO | H14: g.oltorres91@gmail.com | J14: DANIEL CEA COMPRA Y | L14: 1 | M14: 0 | N14: TUR BUS | Q14: CREDITO 30 Y 60 | S14: TIENDA | T14: EVEN EZER | U14: CHAÑARAL | X14: 118 | Y14: 105 | Z14: 13 | AA14: 0.88983051 | AB14: 2900820 | AC14: 143.75
A15: 7.562.033-0 | B15: 75620330 | C15: PATRICIA BARRIA MANCILLA | D15: PORVENIR | E15: JOHN WILLIAMS 034 | F15: 061-2580171 | G15: SERGIO KRAMARENCO | H15: patricia.barria@gmail.com | J15: PATRICIA BARRIA | N15: TRANSCARGO | Q15: CREDITO 30 Y 60 | T15: ROMY'S | U15: PORVENIR | X15: 0 | Y15: 0 | Z15: 0 | AA15: 0 | AB15: 0 | AC15: 0
A16: 7.634.829-4 | B16: 76348294 | C16: CARLOS MELLA ALVARADO | D16: CASTRO | E16: OHIGGINS 658 | F16: 065-2637291 | G16: PATRICIO CUEVAS | H16: tiendamodafiel@gmail.com | J16: SEÑORA SOFIA | L16: 3 | N16: CRUZ DEL SUR | P16: 0 | Q16: CONTRAFACTURA | R16: 9-5791119 | S16: TIENDA Y PAQUETERIA | T16: MODA FIEL | U16: CASTRO | X16: 229 | Y16: 169 | Z16: 60 | AA16: 0.73799127 | AB16: 5766710 | AC16: 248.4
A17: 7.675.412-8 | B17: 76754128 | C17: IRMA ROMERO CASTRO | D17: CURANILAHUE | E17: ARTURO PRAT 1384 | F17: 041/2691287 | G17: PATRICIO CUEVAS | H17: irmafranciscaromero@gmail.com | I17: IRMAFRANCISCAROMERO@GMAIL.COM | J17: IRMA ROMERO | K17: POP DESPACHADO 12/12 | L17: 3 | M17: 0 | N17: CHEVALIER | Q17: CREDITO 30 Y 60 | S17: BOUTIQUE | T17: FRANCISCA ROMERO BOUTIQUE | U17: CURANILAHUE | X17: 0 | Y17: 0 | Z17: 0 | AA17: 0 | AB17: 0 | AC17: 0
A18: 8.259.662-3 | B18: 82596623 | C18: LUIGI ZANDONAI | D18: LA SERENA | E18: BALMACEDA 423 | F18: 51-215122 | G18: HECTOR CAFFIERO | H18: luigizandonay@hotmail.com | J18: LUIGI ZANDONAI | K18: POP DESPACHADO 12/12 | L18: 3 | M18: 0 | N18: PIERO | Q18: CREDITO 30 Y 60 | S18: TIENDA | T18: TIENDA LUIGI ZANDONAI | U18: =D18 | X18: 0 | Y18: 0 | Z18: 0 | AA18: 0 | AB18: 0 | AC18: 48.3
A19: 8.611.778-9 | B19: 86117789 | C19: EMILIA PALMA VILCHES | D19: SAN JAVIER | E19: ARTURO PRAT 2365 | F19: 73-2322862 | G19: CARLOS CUEVAS | H19: mily.palma@gmail.com | J19: MILY PALMA | K19: DUEÑA | L19: 1 | M19: 0 | N19: GEMITA | Q19: CREDITO 30 Y 60 | S19: GRANDES TIENDAS | T19: MILY | U19: SAN JAVIER | V19: SIN INFORMACION COMERCIAL 20/02 | X19: 0 | Y19: 0 | Z19: 0 | AA19: 0 | AB19: 0 | AC19: 0
A20: 8.659.812-4 | B20: 86598124 | C20: RODRIGO EDUARDO SEÑOR LEDESMA | D20: TOME | E20: NOGUEIRA 1137 | F20: 41-2651720 9860610 | G20: PATRICIO CUEVAS | H20: senrodtom@hotmail.com | J20: RODRIGO SEÑOR O MONI | K20: SOCIO | L20: 3 | M20: 0 | N20: VILLA PEAT | Q20: CREDITO 30 Y 60 | S20: VTAS DE PRENDAS DE VESTIR | T20: COMERCIAL LOGROÑO | U20: TOME | V20: SIN INFORMACION COMERCIAL 20/02 | X20: 0 | Y20: 0 | Z20: 0 | AA20: 0 | AB20: 0 | AC20: 0
A21: 8.673.204-1 | B21: 86732041 | C21: ROMAN JUAN CASTRO CAYO | D21: ARICA | E21: AVENIDA 18 DE SEPTIEMBRE 301 L | F21: 58-2232504 | G21: HECTOR CAFFIERO | H21: castro.jade@hotmail.com | J21: ROMAN CASTRO | L21: 1 | M21: 0 | N21: TUR BUS | P21: 0.05 | Q21: CREDITO 30 DIAS | S21: CALZADOS Y ROPAS DE VESTIR | U21: ARICA | X21: 96 | Y21: 73 | Z21: 23 | AA21: 0.76041667 | AB21: 2383040 | AC21: 60.95
A22: 8.780.898-K | B22: 8780898K | C22: PATRICIA HAFON DESMOND | D22: TOCOPILLA | E22: 21 DE MAYO 1549 | F22: 55-812319 | G22: HECTOR CAFFIERO | H22: phafond@hotmail.com | J22: PATRICIA HAFFON | K22: CRISTINA PAGOS | L22: 1 | M22: 0 | N22: RAMOS CHOLELE | Q22: CREDITO 30 Y 60 | S22: BOUTIQUE | U22: =D22 | X22: 0 | Y22: 0 | Z22: 0 | AA22: 0 | AB22: 0 | AC22: 0
A23: 8.837.310-3 | B23: 88373103 | C23: MARIA FRANCISCA IDE SCHMIDT | D23: LA REINA | E23: CARLOS SILVA VILDOSOLA 93 | F23: 2 27586405 | G23: PATRICIO CUEVAS | H23: franciscaides@hotmail.com | J23: SRA FRANCISCA | K23: POP DESPACHADO 11/12 | L23: 3 | M23: 0 | N23: TUR BUS | Q23: CREDITO 30 Y 60 | S23: BOUTIQUE | T23: BOUTIQUE FRANCISCA IDE | U23: LA REINA | X23: 0 | Y23: 0 | Z23: 0 | AA23: 0 | AB23: 0 | AC23: 0
A24: 8.875.220-1 | B24: 88752201 | C24: ANA MARIA CORTES | D24: HUASCO | E24: PEDRO AGUIRRE CERDA 316 | F24: 51-531308 | G24: HECTOR CAFFIERO | H24: cgonza77@hotmail.com | J24: CARLA GONZALEZ | L24: 2 | M24: 0 | N24: TUR BUS | Q24: CREDITO30 DIAS | S24: TIENDA BAZAR Y PAQUETERIA | T24: ANA MARIA BOUTIQUE | U24: =D24 | X24: 0 | Y24: 0 | Z24: 0 | AA24: 0 | AB24: 0 | AC24: 0
A25: 8.990.492-7 | B25: 89904927 | C25: LEYLA DEL CAMPO CASTRO | D25: PUERTO AYSEN | E25: ARTURO PRAT 735 | F25: 067-336824 | G25: SERGIO KRAMARENCO | H25: oleyboutique@gmail.com | J25: LEYLA DEL CAMPO | K25: DUEÑA DE LA TIENDA | L25: 3 | M25: 0 | N25: ATE | Q25: TRANSF. CONTRA ENTREGA | S25: BOUTIQUE | T25: OLEY BOUTIQUE | U25: PUERTO AYSEN | X25: 0 | Y25: 0 | Z25: 0 | AA25: 0 | AB25: 0 | AC25: 0
A26: 9.016.604-2 | B26: 90166042 | C26: RODRIGO SALDIVIA REMOLCOY | D26: QUELLON | E26: LADRILLERO 075 | F26: 65/682901 65/683414 | G26: PATRICIO CUEVAS | H26: lucre_esve1@hotmail.com | J26: LUCRESIA ESCANDON | K26: POP DESPACHADO 12/12 | L26: 4 | M26: 0 | N26: CRUZ DEL SUR | Q26: CREDITO 30 Y 60 | X26: 0 | Y26: 0 | Z26: 0 | AA26: 0 | AB26: 0 | AC26: 0
A27: 9.276.152-5 | B27: 92761525 | C27: CARMEN GLORIA GALLARDO VALERIO | D27: LA UNION | E27: COMERCIO 400 | F27: 64-425041 | G27: PATRICIO CUEVAS | H27: ricardo_lmunoz@yahoo.com | J27: RICARDO MUÑOZ | K27: POP DESPACHADO 12/12 | L27: 3 | M27: 0 | N27: CHEVALIER | Q27: CREDITO 30 Y 60 | S27: TIENDA | T27: PIBAS | U27: LA UNION | X27: 252 | Y27: 179 | Z27: 73 | AA27: 0.71031746 | AB27: 6290480 | AC27: 287.5
A28: 9.305.252-8 | B28: 93052528 | C28: SABINA QUISPE PAIRO | D28: ARICA | E28: 18 SEPTIEMBRE 301 LOCAL 4 | F28: 58-251824 LOCAL | G28: HECTOR CAFFIERO | H28: constanzacontreras1310@gmail.com | J28: SABINA QUISPE | K28: MARLON ZAPATA | L28: 1 | M28: 0 | N28: CHACON | Q28: CREDITO 30 Y 60 | S28: BOUTIQUE | T28: SABY SPORT | U28: ARICA | X28: 196 | Y28: 171 | Z28: 25 | AA28: 0.87244898 | AB28: 4906040 | AC28: 439.3
A29: 9.434.963-K | B29: 9434963K | C29: ROSA EMILIA FUENTES MANCILLA | D29: QUEILEN | E29: PEDRO AGUIRRE CERDA 183 | F29: 65/611209 611543 | G29: PATRICIO CUEVAS | H29: rosa.fuentes.23@gmail.com | J29: ROSA FUENTES MANCILL | K29: VERONICA PAGOS | L29: 3 | M29: 0 | N29: CRUZ DEL SUR | Q29: TRANSF. CONTRA ENTREGA | S29: TIENDA | T29: TIENDA Y PAQUETERIA ROCIO | U29: QUEILEN | X29: 0 | Y29: 0 | Z29: 0 | AA29: 0 | AB29: 0 | AC29: 0
A30: 9.684.131-0 | B30: 96841310 | C30: NEDY BASCUNAN MANSILLA | D30: COYHAIQUE | E30: ERRAZURIZ 261-A | F30: 67-245741 | G30: SERGIO KRAMARENCO | H30: nedybascunan@gmail.com | J30: NEDY | K30: 41619 | L30: 1 | M30: 0 | N30: TRANSMAX | Q30: CONTADO | S30: TIENDA | T30: BOUTIQUE FRANCHESCA | U30: COYHAIQUE | X30: 0 | Y30: 0 | Z30: 0 | AA30: 0 | AB30: 0 | AC30: 345
A31: 9.804.121-4 | B31: 98041214 | C31: MARIA CONCHA CACERES | D31: CONSTITUCION | E31: VIAL 380 A | F31: 71-2673006 | G31: PATRICIO CUEVAS | H31: mariaconcha-63@hotmail.co | J31: MARIA CONCHA CACERES | K31: DUEÑA | L31: 3 | M31: 0 | N31: EMECOL | Q31: CREDITO 30 Y 60 | S31: TIENDA | T31: TRIBAL | U31: CONSTITUCION | X31: 0 | Y31: 0 | Z31: 0 | AA31: 0 | AB31: 0 | AC31: 0
A32: 10.026.410-2 | B32: 100264102 | C32: GLORIA CONTRERAS TORRES | D32: COCHRANNE | E32: RIO COLONIAL 560 | F32: 67-552734 | G32: SERGIO KRAMARENCO | H32: gcontrerastorres@hotmail.cl | J32: GLORIA CONTRERAS | L32: 3 | M32: 0 | N32: ATE | Q32: TRANSF. CONTRA ENTREGA | S32: VENTAS PRENDAS DE VESTIR | U32: COCHRANE | V32: DICOM OK AL 27/2 | X32: 0 | Y32: 0 | Z32: 0 | AA32: 0 | AB32: 0 | AC32: 37.95
A33: 10.270.508-4 | B33: 102705084 | C33: ELIANA VENTURELLI REGLA | D33: CAP. PASTENE | E33: PEDRO MONTT 640 | F33: 84092579 | G33: PATRICIO CUEVAS | H33: elianaventurelliregla@hotmail. | J33: ELIANA VENTURELLI | K33: POP DESPACHADO 12/12 | L33: 3 | M33: 0 | N33: JC | Q33: CHEQUE 30 DIAS | S33: BOUTIQUE | U33: TRAIGUEN | V33: SIN INFORMACION COMERCIAL 20/02 | X33: 64 | Y33: 62 | Z33: 2 | AA33: 0.96875 | AB33: 1573360 | AC33: 36.8
A34: 10.529.776-9 | B34: 105297769 | C34: OLGA OLIVIA POBLETE CONCHA | D34: TRAIGUEN | E34: LAGOS 957 | F34: 950866511 | G34: CARLOS CUEVAS | H34: OLGAPOBLETECONCHA@GMAIL.COM | J34: OLGA POBLETE | L34: 3 | N34: BUSES JC | Q34: TRANSF. CONTRAFACTURA | R34: 0 | S34: BOUTIQUE | T34: FENIX BOUTIQUE | X34: 96 | Y34: 70 | Z34: 26 | AA34: 0.72916667 | AB34: 2423040 | AC34: 70.15
A35: 10.777.684-2 | B35: 107776842 | C35: KETTY ROJAS RAMIREZ | D35: COPIAPO | E35: VILLA DIEGO PORTALES C/11 | F35: 052/241236 | G35: HECTOR CAFFIERO | H35: krojasramirez@gmail.com | L35: 4 | M35: 0 | N35: ENVIAS EXPRESS | Q35: CREDITO 30 Y 60 | S35: TIENDA | X35: 0 | Y35: 0 | Z35: 0 | AA35: 0 | AB35: 0 | AC35: 0
A36: 10.879.819-K | B36: 10879819K | C36: CELIA VASQUEZ BARRERA | D36: VILLARRICA | E36: PEDRO DE VALDIVIA 650 LOCAL 25 | F36: 045-2412431 | G36: PATRICIO CUEVAS | H36: prodigos@live.cl | J36: CELIA VASQUEZ | K36: POP DESPACHADO 11/12 | L36: 1 | M36: 0 | N36: TUR BUS | P36: 0.05 | Q36: CONTADO | T36: PRODIGOS | U36: VILLARRICA | V36: NO CUMPLE PERFIL PARA MOHICANO | X36: 58 | Y36: 56 | Z36: 2 | AA36: 0.96551724 | AB36: 1441420 | AC36: 49.45
A37: 11.354.049-4 | B37: 113540494 | C37: PATRICIA MENA SANDOVAL | D37: TRAIGUEN | E37: AV SAAVEDRA 460 | F37: 045-861873 | G37: PATRICIO CUEVAS | H37: patcemesa@hotmail.com | J37: PATRICIA MENA | L37: 3 | M37: 0 | Q37: CREDITO 30 Y 60 | S37: BOUTIQUE | T37: PATY MENA BOUTIQUE | U37: TRAIGUEN | X37: 0 | Y37: 0 | Z37: 0 | AA37: 0 | AB37: 0 | AC37: 0
A38: 11.407.997-9 | B38: 114079979 | C38: DANITZA OSSES AEDO | D38: TRAIGUEN | E38: CALLE SANTA CRUZ Nº 807 | F38: 45-861192 | G38: PATRICIO CUEVAS | H38: danitzaosses@hotmail.com | J38: DANITZA OSSES | K38: DUEÑA | L38: 3 | M38: 0 | Q38: CREDITO 30 Y 60 | V38: TRANSPORTES JAC , SIN INFORMES COMERCIALES 20/02 | X38: 73 | Y38: 63 | Z38: 10 | AA38: 0.8630137 | AB38: 1798270 | AC38: 50.6
A39: 11.564.359-2 | B39: 115643592 | C39: BELLA FUENTES PINCHEIRA | D39: LINARES | E39: CHACABUCO 435 LOCAL 03 | F39: 73-2219931 | G39: PATRICIO CUEVAS | H39: befupi@gmail.com | J39: BELLA FUENTES | K39: POP DESPACHADO 12/12 | L39: 1 | M39: 0 | N39: CHEVALIER | P39: 0.05 | Q39: CONTADO | R39: 98376422 | S39: BOUTIQUE BAZAR Y PAQUETERIA | T39: D JAVI | U39: LINARES | V39: CANCELA CHEQUE 30 DIAS CON 10% DE DESCUENTO, SU ENCARGADA DE LOCAL ES MINERVA | X39: 480 | Y39: 446 | Z39: 34 | AA39: 0.92916667 | AB39: 11887200 | AC39: 500.25
A40: 11.684.129-0 | B40: 116841290 | C40: HUGO MONTERO FIGUEROA | D40: LOS ANGELES | E40: VALDIVIA 487 LOCAL L | G40: PATRICIO CUEVAS | H40: hugomonterof@yahoo.es | J40: HUGO MONTERO | K40: DUEÑO | L40: 1 | M40: 0 | N40: CHEVALIER | Q40: 30 DIAS | R40: 09-3447832 | S40: TIENDAS | T40: HECHIZOS | U40: LOS ANGELES | V40: TRANSPORTE CHEVALIER | X40: 335 | Y40: 330 | Z40: 5 | AA40: 0.98507463 | AB40: 8369650 | AC40: 385.25
A41: 12.003.736-6 | B41: 120037366 | C41: ARMANDO BARRIA LEGUE | D41: PUERTO NATALES | E41: MANUEL BULNES 731 LOCAL A | F41: 061-413977 | G41: SERGIO KRAMARENCO | H41: tiendarmando@gmial.com | J41: ARMANDO BARRIA | L41: 3 | M41: 0 | N41: TRANSCARGO | Q41: TRANSF. CONTRA ENTREGA | S41: TIENDA | T41: ESPACIO JEANS | U41: PUERTO NATALES | X41: 182 | Y41: 181 | Z41: 1 | AA41: 0.99450549 | AB41: 4475180 | AC41: 218.5
...

Sheet BASE DE DATOS OFICIAL
A1: 1 | B1: 1 | C1: 2 | D1: 3 | E1: 4 | F1: 5 | G1: 6 | H1: 7 | I1: 8 | J1: 9 | K1: 10 | L1: 11 | M1: 12 | N1: 13 | O1: 14 | P1: 15 | Q1: 16 | R1: 17 | S1: 18 | T1: 19 | U1: 20 | V1: 21 | W1: 22 | X1: 23 | Y1: 24 | Z1: 25 | AA1: 26 | AB1: 27 | AC1: 28
A3: RUT | B3: RUT2 | C3: Razon Social | D3: Ciudad | E3: Direccion | F3: Fono | G3: Vendedor | H3: Correo | I3: WWW | J3: Contacto | K3: Cargo | L3: GRUPO | M3: Credito | N3: Transporte | O3: BLOQUEADO | P3: Dcto | Q3: CONDICION DE PAGO | R3: CELULAR | S3: GIRO | T3: NOMBRE DE TIENDA | U3: COMUNA | V3: Observaciones | W3: Ped_anterior | X3: Cantidad | Y3: Despacho | Z3: Saldo | AA3: % Despacho | AB3: Valor | AC3: Meta Cole-38
A4: 4.878.758-4 | B4: 48787584 | C4: ROBERTO KOBUS PEMSO | D4: ANCUD | E4: PUDETO 143-145 | F4: 998269854 | G4: PATRICIO CUEVAS | H4: tiendasmachos@gmail.com | I4: MACHOS BOUTIQUE@SURNET.CL | J4: JENIFER PAGOS | L4: 4 | M4: 0 | N4: VARMONTT | Q4: CREDITO 30 Y 60 | S4: GRANDES TIENDAS | T4: MACHOS | U4: ANCUD | V4: VARMONTT | X4: 505 | Y4: 438 | Z4: =SUM(X4-Y4) | AA4: 0.88706366 | AB4: 11150620 | AC4: 782
A5: 5.001.562-9 | B5: 50015629 | C5: INES VARGAS PINO | D5: COPIAPO | E5: ATACAMA 461-A | F5: 52-213939 | G5: HECTOR CAFFIERO | J5: INES VARGAS | L5: 3 | M5: 0 | N5: SER VALL | P5: 0.05 | Q5: TRANSF. CONTRA FACTURA | R5: 8-8637797 | S5: TIENDA DE VESTIR | T5: BOUTIQUE GEMINIS | U5: COPIAPO | X5: 0 | Y5: 0 | Z5: =SUM(X5-Y5) | AA5: 0 | AB5: 0 | AC5: 0
A6: 5.384.900-8 | B6: 53849008 | C6: ELIANA RIQUELME R. | D6: FUTRONO | E6: BALMACEDA 249 | F6: 966322618 | G6: PATRICIO CUEVAS | J6: ELIANA RIQUELME | L6: 4 | M6: 0 | N6: TUR BUS | Q6: CREDITO 30 Y 60 | S6: VENTAS | T6: COSAS BOUTIQUE | U6: FUTRONO | X6: 0 | Y6: 0 | Z6: =SUM(X6-Y6) | AA6: 0 | AB6: 0 | AC6: 0
A7: 5.913.365-9 | B7: 59133659 | C7: ANA MARIA MANFREDI CARRASCO | D7: OVALLE | E7: VICUÑA MACKENNA 287 | F7: 053-622626 | G7: HECTOR CAFFIERO | H7: manfredi@hotmail.com | J7: DANIELA O ANA MARIA | K7: DUEÑO | L7: 3 | M7: 0 | N7: CHILE LINDO | Q7: CREDITO 30 Y 60 | S7: VENTAS AL POR MENOR | T7: BOUTIQUE PARA TI | U7: =D7 | X7: 118 | Y7: 107 | Z7: =SUM(X7-Y7) | AA7: 0.63736264 | AB7: 2688930 | AC7: 186.3
A8: 6.031.123-4 | B8: 60311234 | C8: FABIOLA BENAVENTE MEZA | D8: PARRAL | E8: ANIBAL PINTO 590 | F8: 961895384 | G8: CARLOS CUEVAS | H8: tiendaelegance@gmail.com | J8: FABIOLA BENAVENTE | K8: POP DESPACHADO 11/12 | L8: 3 | M8: 0 | N8: VILLA PRAT | Q8: CONTRAFACTURA | S8: BOUTIQUE | T8: ELEGANTE BOUTIQUE | U8: PARRAL | X8: 62 | Y8: 55 | Z8: =SUM(X8-Y8) | AA8: 0.97777778 | AB8: 1399450 | AC8: 51.75
A9: 6.331.910-4 | B9: 63319104 | C9: LUIS SOUMASTRE RAMIREZ | D9: ARICA | E9: 21 DE MAYO 454 | F9: 058-2232959 | G9: HECTOR CAFFIERO | H9: lfsr24@hotmail.com | J9: gloria tapia | L9: 3 | M9: 0 | N9: CHACON | Q9: CREDITO 30 Y 60 | S9: VENTAS AL POR MENOR | U9: ARICA | X9: 71 | Y9: 65 | Z9: =SUM(X9-Y9) | AA9: 0 | AB9: 1665350 | AC9: 26.45
A10: 6.589.904-3 | B10: 65899043 | C10: ANITA BERTA GADICKE | D10: OSORNO | E10: OHIGGINS 534 | F10: 985067217 | G10: PATRICIO CUEVAS | H10: anitagadicke@gmail.com | J10: ANITA GADICKE | L10: 4 | M10: 0 | N10: CIDHER | Q10: CREDITO 30 Y 60 | S10: BOUTIQUE | T10: ALBANY SPORT | U10: OSORNO | X10: 0 | Y10: 0 | Z10: =SUM(X10-Y10) | AA10: 0 | AB10: 0 | AC10: 0
A11: 6.775.324-0 | B11: 67753240 | C11: MARIA DE LOS ANGELES DIAZ BELLIDO | D11: VILLA ALEMANA | E11: BUENOS AIRE 845 | F11: 32-2951011 | G11: PATRICIO CUEVAS | H11: balaustros2@hotmail.com | I11: BALASUTROSVILLAALEMANA@GMAIL.C | J11: MARIA DE LOS ANGELES | L11: 4 | N11: ABC | Q11: CREDITO 30 Y 60 | S11: BOUTIQUE | T11: BALAUSTROS BOUTIQUE | U11: VILLA ALEMANA | X11: 0 | Y11: 0 | Z11: =SUM(X11-Y11) | AA11: 0 | AB11: 0 | AC11: 0
A12: 6.799.967-3 | B12: 67999673 | C12: 3 | D12: CABILDO | E12: HUMERES 727 | F12: 91286053 | G12: CARLOS CUEVAS | H12: anisalta@hotmail.com | J12: ANA MARIA SALVATIERR | L12: 3 | M12: 0 | N12: RETIRA Sn Gerardo | Q12: CREDITO 30 Y 60 | S12: BOUTIQUE | T12: BOUTIQUE ANITA | U12: CABILDO | X12: 36 | Y12: 36 | Z12: =SUM(X12-Y12) | AA12: 0.97777778 | AB12: 917640 | AC12: 216.2
A13: 76.965.431-3 | B13: 769654313 | C13: OPALO VESTUARIO | D13: CONCEPCION | E13: BARROS ARANA 815 LOCAL 14 | F13: 991959818 | G13: PATRICIO CUEVAS | H13: mayobenites@hotmail.com | J13: HILIA CONCHA | K13: DUEÑA | L13: 1 | M13: 0 | N13: CHEVALIER | Q13: CHEQUE 30 DIAS | R13: 99594046 | S13: BOUTIQUE | T13: OPALO BOUTIQUE | U13: CONCEPCION | V13: HIJA MARJORIE BENITEZ, TRANSPORTE CHEVALIER 13/11 | X13: 704 | Y13: 555 | Z13: =SUM(X13-Y13) | AA13: 0.70772443 | AB13: 14347450 | AC13: 635.95
A14: 7.096.837-1 | B14: 70968371 | C14: GLORIA CECILIA OLIVARES TORRES | D14: CHAÑARAL | E14: MERINO JARPA 590 | F14: 09-98175762 | G14: HECTOR CAFFIERO | H14: g.oltorres91@gmail.com | J14: DANIEL CEA COMPRA Y | L14: 1 | M14: 0 | N14: TUR BUS | Q14: CREDITO 30 Y 60 | S14: TIENDA | T14: EVEN EZER | U14: CHAÑARAL | X14: 130 | Y14: 125 | Z14: =SUM(X14-Y14) | AA14: 0.88983051 | AB14: 3238750 | AC14: 143.75
A15: 7.562.033-0 | B15: 75620330 | C15: PATRICIA BARRIA MANCILLA | D15: PORVENIR | E15: JOHN WILLIAMS 034 | F15: 061-2580171 | G15: SERGIO KRAMARENCO | H15: patricia.barria@gmail.com | J15: PATRICIA BARRIA | N15: TRANSCARGO | Q15: CREDITO 30 Y 60 | T15: ROMY'S | U15: PORVENIR | X15: 0 | Y15: 0 | Z15: =SUM(X15-Y15) | AA15: 0 | AB15: 0 | AC15: 0
A16: 7.634.829-4 | B16: 76348294 | C16: CARLOS MELLA ALVARADO | D16: CASTRO | E16: OHIGGINS 658 | F16: 065-2637291 | G16: PATRICIO CUEVAS | H16: tiendamodafiel@gmail.com | J16: SEÑORA SOFIA | L16: 3 | N16: CRUZ DEL SUR | P16: 0 | Q16: CONTRAFACTURA | R16: 9-5791119 | S16: TIENDA Y PAQUETERIA | T16: MODA FIEL | U16: CASTRO | X16: 259 | Y16: 221 | Z16: =SUM(X16-Y16) | AA16: 0.73799127 | AB16: 5596790 | AC16: 248.4
A17: 7.675.412-8 | B17: 76754128 | C17: IRMA ROMERO CASTRO | D17: CURANILAHUE | E17: ARTURO PRAT 1384 | F17: 041/2691287 | G17: PATRICIO CUEVAS | H17: irmafranciscaromero@gmail.com | I17: IRMAFRANCISCAROMERO@GMAIL.COM | J17: IRMA ROMERO | K17: POP DESPACHADO 12/12 | L17: 3 | M17: 0 | N17: CHEVALIER | Q17: CREDITO 30 Y 60 | S17: BOUTIQUE | T17: FRANCISCA ROMERO BOUTIQUE | U17: CURANILAHUE | X17: 0 | Y17: 0 | Z17: =SUM(X17-Y17) | AA17: 0 | AB17: 0 | AC17: 0
A18: 8.259.662-3 | B18: 82596623 | C18: LUIGI ZANDONAI | D18: LA SERENA | E18: BALMACEDA 423 | F18: 51-215122 | G18: HECTOR CAFFIERO | H18: luigizandonay@hotmail.com | J18: LUIGI ZANDONAI | K18: POP DESPACHADO 12/12 | L18: 3 | M18: 0 | N18: PIERO | Q18: CREDITO 30 Y 60 | S18: TIENDA | T18: TIENDA LUIGI ZANDONAI | U18: =D18 | X18: 0 | Y18: 0 | Z18: =SUM(X18-Y18) | AA18: 0 | AB18: 0 | AC18: 48.3
A19: 8.611.778-9 | B19: 86117789 | C19: EMILIA PALMA VILCHES | D19: SAN JAVIER | E19: ARTURO PRAT 2365 | F19: 73-2322862 | G19: CARLOS CUEVAS | H19: mily.palma@gmail.com | J19: MILY PALMA | K19: DUEÑA | L19: 1 | M19: 0 | N19: GEMITA | Q19: CREDITO 30 Y 60 | S19: GRANDES TIENDAS | T19: MILY | U19: SAN JAVIER | V19: SIN INFORMACION COMERCIAL 20/02 | X19: 0 | Y19: 0 | Z19: =SUM(X19-Y19) | AA19: 0 | AB19: 0 | AC19: 0
A20: 8.659.812-4 | B20: 86598124 | C20: RODRIGO EDUARDO SEÑOR LEDESMA | D20: TOME | E20: NOGUEIRA 1137 | F20: 41-2651720 9860610 | G20: PATRICIO CUEVAS | H20: senrodtom@hotmail.com | J20: RODRIGO SEÑOR O MONI | K20: SOCIO | L20: 3 | M20: 0 | N20: VILLA PEAT | Q20: CREDITO 30 Y 60 | S20: VTAS DE PRENDAS DE VESTIR | T20: COMERCIAL LOGROÑO | U20: TOME | V20: SIN INFORMACION COMERCIAL 20/02 | X20: 0 | Y20: 0 | Z20: =SUM(X20-Y20) | AA20: 0 | AB20: 0 | AC20: 0
A21: 8.673.204-1 | B21: 86732041 | C21: ROMAN JUAN CASTRO CAYO | D21: ARICA | E21: AVENIDA 18 DE SEPTIEMBRE 301 L | F21: 58-2232504 | G21: HECTOR CAFFIERO | H21: castro.jade@hotmail.com | J21: ROMAN CASTRO | L21: 1 | M21: 0 | N21: TUR BUS | P21: 0.05 | Q21: CREDITO 30 DIAS | S21: CALZADOS Y ROPAS DE VESTIR | U21: ARICA | X21: 41 | Y21: 42 | Z21: =SUM(X21-Y21) | AA21: 0.76041667 | AB21: 1057580 | AC21: 60.95
A22: 8.780.898-K | B22: 8780898K | C22: PATRICIA HAFON DESMOND | D22: TOCOPILLA | E22: 21 DE MAYO 1549 | F22: 55-812319 | G22: HECTOR CAFFIERO | H22: phafond@hotmail.com | J22: PATRICIA HAFFON | K22: CRISTINA PAGOS | L22: 1 | M22: 0 | N22: RAMOS CHOLELE | Q22: CREDITO 30 Y 60 | S22: BOUTIQUE | U22: =D22 | X22: 8 | Y22: 0 | Z22: =SUM(X22-Y22) | AA22: 0 | AB22: 0 | AC22: 0
A23: 8.837.310-3 | B23: 88373103 | C23: MARIA FRANCISCA IDE SCHMIDT | D23: LA REINA | E23: CARLOS SILVA VILDOSOLA 93 | F23: 2 27586405 | G23: PATRICIO CUEVAS | H23: franciscaides@hotmail.com | J23: SRA FRANCISCA | K23: POP DESPACHADO 11/12 | L23: 3 | M23: 0 | N23: TUR BUS | Q23: CREDITO 30 Y 60 | S23: BOUTIQUE | T23: BOUTIQUE FRANCISCA IDE | U23: LA REINA | X23: 0 | Y23: 0 | Z23: =SUM(X23-Y23) | AA23: 0 | AB23: 0 | AC23: 0
A24: 8.875.220-1 | B24: 88752201 | C24: ANA MARIA CORTES | D24: HUASCO | E24: PEDRO AGUIRRE CERDA 316 | F24: 51-531308 | G24: HECTOR CAFFIERO | H24: cgonza77@hotmail.com | J24: CARLA GONZALEZ | L24: 2 | M24: 0 | N24: TUR BUS | Q24: CREDITO30 DIAS | S24: TIENDA BAZAR Y PAQUETERIA | T24: ANA MARIA BOUTIQUE | U24: =D24 | X24: 0 | Y24: 0 | Z24: =SUM(X24-Y24) | AA24: 0 | AB24: 0 | AC24: 0
A25: 8.990.492-7 | B25: 89904927 | C25: LEYLA DEL CAMPO CASTRO | D25: PUERTO AYSEN | E25: ARTURO PRAT 735 | F25: 067-336824 | G25: SERGIO KRAMARENCO | H25: oleyboutique@gmail.com | J25: LEYLA DEL CAMPO | K25: DUEÑA DE LA TIENDA | L25: 3 | M25: 0 | N25: ATE | Q25: TRANSF. CONTRA ENTREGA | S25: BOUTIQUE | T25: OLEY BOUTIQUE | U25: PUERTO AYSEN | X25: 0 | Y25: 0 | Z25: =SUM(X25-Y25) | AA25: 0 | AB25: 0 | AC25: 0
A26: 9.016.604-2 | B26: 90166042 | C26: RODRIGO SALDIVIA REMOLCOY | D26: QUELLON | E26: LADRILLERO 075 | F26: 65/682901 65/683414 | G26: PATRICIO CUEVAS | H26: lucre_esve1@hotmail.com | J26: LUCRESIA ESCANDON | K26: POP DESPACHADO 12/12 | L26: 4 | M26: 0 | N26: CRUZ DEL SUR | Q26: CREDITO 30 Y 60 | X26: 0 | Y26: 0 | Z26: =SUM(X26-Y26) | AA26: 0 | AB26: 0 | AC26: 0
A27: 9.276.152-5 | B27: 92761525 | C27: CARMEN GLORIA GALLARDO VALERIO | D27: LA UNION | E27: COMERCIO 400 | F27: 64-425041 | G27: PATRICIO CUEVAS | H27: ricardo_lmunoz@yahoo.com | J27: RICARDO MUÑOZ | K27: POP DESPACHADO 12/12 | L27: 3 | M27: 0 | N27: CHEVALIER | Q27: CREDITO 30 Y 60 | S27: TIENDA | T27: PIBAS | U27: LA UNION | X27: 121 | Y27: 106 | Z27: =SUM(X27-Y27) | AA27: 0.71031746 | AB27: 2771940 | AC27: 287.5
A28: 9.305.252-8 | B28: 93052528 | C28: SABINA QUISPE PAIRO | D28: ARICA | E28: 18 SEPTIEMBRE 301 LOCAL 4 | F28: 58-251824 LOCAL | G28: HECTOR CAFFIERO | H28: constanzacontreras1310@gmail.com | J28: SABINA QUISPE | K28: MARLON ZAPATA | L28: 1 | M28: 0 | N28: CHACON | Q28: CREDITO 30 Y 60 | S28: BOUTIQUE | T28: SABY SPORT | U28: ARICA | X28: 553 | Y28: 441 | Z28: =SUM(X28-Y28) | AA28: 0.87244898 | AB28: 11312590 | AC28: 439.3
A29: 9.434.963-K | B29: 9434963K | C29: ROSA EMILIA FUENTES MANCILLA | D29: QUEILEN | E29: PEDRO AGUIRRE CERDA 183 | F29: 65/611209 611543 | G29: PATRICIO CUEVAS | H29: rosa.fuentes.23@gmail.com | J29: ROSA FUENTES MANCILL | K29: VERONICA PAGOS | L29: 3 | M29: 0 | N29: CRUZ DEL SUR | Q29: TRANSF. CONTRA ENTREGA | S29: TIENDA | T29: TIENDA Y PAQUETERIA ROCIO | U29: QUEILEN | X29: 0 | Y29: 0 | Z29: =SUM(X29-Y29) | AA29: 0 | AB29: 0 | AC29: 0
A30: 9.684.131-0 | B30: 96841310 | C30: NEDY BASCUNAN MANSILLA | D30: COYHAIQUE | E30: ERRAZURIZ 261-A | F30: 67-245741 | G30: SERGIO KRAMARENCO | H30: nedybascunan@gmail.com | J30: NEDY | K30: 41619 | L30: 1 | M30: 0 | N30: TRANSMAX | Q30: CONTADO | S30: TIENDA | T30: BOUTIQUE FRANCHESCA | U30: COYHAIQUE | X30: 0 | Y30: 0 | Z30: =SUM(X30-Y30) | AA30: 0 | AB30: 0 | AC30: 345
A31: 9.804.121-4 | B31: 98041214 | C31: MARIA CONCHA CACERES | D31: CONSTITUCION | E31: VIAL 380 A | F31: 71-2673006 | G31: PATRICIO CUEVAS | H31: mariaconcha-63@hotmail.co | J31: MARIA CONCHA CACERES | K31: DUEÑA | L31: 3 | M31: 0 | N31: EMECOL | Q31: CREDITO 30 Y 60 | S31: TIENDA | T31: TRIBAL | U31: CONSTITUCION | X31: 0 | Y31: 0 | Z31: =SUM(X31-Y31) | AA31: 0 | AB31: 0 | AC31: 0
A32: 10.026.410-2 | B32: 100264102 | C32: GLORIA CONTRERAS TORRES | D32: COCHRANNE | E32: RIO COLONIAL 560 | F32: 67-552734 | G32: SERGIO KRAMARENCO | H32: gcontrerastorres@hotmail.cl | J32: GLORIA CONTRERAS | L32: 3 | M32: 0 | N32: ATE | Q32: TRANSF. CONTRA ENTREGA | S32: VENTAS PRENDAS DE VESTIR | U32: COCHRANE | V32: DICOM OK AL 27/2 | X32: 0 | Y32: 0 | Z32: =SUM(X32-Y32) | AA32: 0 | AB32: 0 | AC32: 37.95
A33: 10.270.508-4 | B33: 102705084 | C33: ELIANA VENTURELLI REGLA | D33: CAP. PASTENE | E33: PEDRO MONTT 640 | F33: 84092579 | G33: PATRICIO CUEVAS | H33: elianaventurelliregla@hotmail. | J33: ELIANA VENTURELLI | K33: POP DESPACHADO 12/12 | L33: 3 | M33: 0 | N33: JC | Q33: CHEQUE 30 DIAS | S33: BOUTIQUE | U33: TRAIGUEN | V33: SIN INFORMACION COMERCIAL 20/02 | X33: 190 | Y33: 121 | Z33: =SUM(X33-Y33) | AA33: 0.96875 | AB33: 3051790 | AC33: 36.8
A34: 10.529.776-9 | B34: 105297769 | C34: OLGA OLIVIA POBLETE CONCHA | D34: TRAIGUEN | E34: LAGOS 957 | F34: 950866511 | G34: CARLOS CUEVAS | H34: OLGAPOBLETECONCHA@GMAIL.COM | J34: OLGA POBLETE | L34: 3 | N34: BUSES JC | Q34: TRANSF. CONTRAFACTURA | R34: 0 | S34: BOUTIQUE | T34: FENIX BOUTIQUE | X34: 96 | Y34: 70 | Z34: =SUM(X34-Y34) | AA34: 0.72916667 | AB34: 2423040 | AC34: 70.15
A35: 10.777.684-2 | B35: 107776842 | C35: KETTY ROJAS RAMIREZ | D35: COPIAPO | E35: VILLA DIEGO PORTALES C/11 | F35: 052/241236 | G35: HECTOR CAFFIERO | H35: krojasramirez@gmail.com | L35: 4 | M35: 0 | N35: ENVIAS EXPRESS | Q35: CREDITO 30 Y 60 | S35: TIENDA | X35: 0 | Y35: 0 | Z35: =SUM(X35-Y35) | AA35: 0 | AB35: 0 | AC35: 0
A36: 10.879.819-K | B36: 10879819K | C36: CELIA VASQUEZ BARRERA | D36: VILLARRICA | E36: PEDRO DE VALDIVIA 650 LOCAL 25 | F36: 045-2412431 | G36: PATRICIO CUEVAS | H36: prodigos@live.cl | J36: CELIA VASQUEZ | K36: POP DESPACHADO 11/12 | L36: 1 | M36: 0 | N36: TUR BUS | P36: 0.05 | Q36: CONTADO | T36: PRODIGOS | U36: VILLARRICA | V36: NO CUMPLE PERFIL PARA MOHICANO | X36: 49 | Y36: 40 | Z36: =SUM(X36-Y36) | AA36: 0.96551724 | AB36: 1006600 | AC36: 49.45
A37: 11.354.049-4 | B37: 113540494 | C37: PATRICIA MENA SANDOVAL | D37: TRAIGUEN | E37: AV SAAVEDRA 460 | F37: 045-861873 | G37: PATRICIO CUEVAS | H37: patcemesa@hotmail.com | J37: PATRICIA MENA | L37: 3 | M37: 0 | Q37: CREDITO 30 Y 60 | S37: BOUTIQUE | T37: PATY MENA BOUTIQUE | U37: TRAIGUEN | X37: 0 | Y37: 0 | Z37: =SUM(X37-Y37) | AA37: 0 | AB37: 0 | AC37: 0
A38: 11.407.997-9 | B38: 114079979 | C38: DANITZA OSSES AEDO | D38: TRAIGUEN | E38: CALLE SANTA CRUZ Nº 807 | F38: 45-861192 | G38: PATRICIO CUEVAS | H38: danitzaosses@hotmail.com | J38: DANITZA OSSES | K38: DUEÑA | L38: 3 | M38: 0 | Q38: CREDITO 30 Y 60 | V38: TRANSPORTES JAC , SIN INFORMES COMERCIALES 20/02 | X38: 106 | Y38: 95 | Z38: =SUM(X38-Y38) | AA38: 0.8630137 | AB38: 2438050 | AC38: 50.6
A39: 11.564.359-2 | B39: 115643592 | C39: BELLA FUENTES PINCHEIRA | D39: LINARES | E39: CHACABUCO 435 LOCAL 03 | F39: 73-2219931 | G39: PATRICIO CUEVAS | H39: befupi@gmail.com | J39: BELLA FUENTES | K39: POP DESPACHADO 12/12 | L39: 1 | M39: 0 | N39: CHEVALIER | P39: 0.05 | Q39: CONTADO | R39: 98376422 | S39: BOUTIQUE BAZAR Y PAQUETERIA | T39: D JAVI | U39: LINARES | V39: CANCELA CHEQUE 30 DIAS CON 10% DE DESCUENTO, SU ENCARGADA DE LOCAL ES MINERVA | X39: 623 | Y39: 497 | Z39: =SUM(X39-Y39) | AA39: 0.92916667 | AB39: 12767030 | AC39: 500.25
A40: 11.684.129-0 | B40: 116841290 | C40: HUGO MONTERO FIGUEROA | D40: LOS ANGELES | E40: VALDIVIA 487 LOCAL L | G40: PATRICIO CUEVAS | H40: hugomonterof@yahoo.es | J40: HUGO MONTERO | K40: DUEÑO | L40: 1 | M40: 0 | N40: CHEVALIER | Q40: 30 DIAS | R40: 09-3447832 | S40: TIENDAS | T40: HECHIZOS | U40: LOS ANGELES | V40: TRANSPORTE CHEVALIER | X40: 397 | Y40: 380 | Z40: =SUM(X40-Y40) | AA40: 0.98507463 | AB40: 9639200 | AC40: 385.25
A41: 12.003.736-6 | B41: 120037366 | C41: ARMANDO BARRIA LEGUE | D41: PUERTO NATALES | E41: MANUEL BULNES 731 LOCAL A | F41: 061-413977 | G41: SERGIO KRAMARENCO | H41: tiendarmando@gmial.com | J41: ARMANDO BARRIA | L41: 3 | M41: 0 | N41: TRANSCARGO | Q41: TRANSF. CONTRA ENTREGA | S41: TIENDA | T41: ESPACIO JEANS | U41: PUERTO NATALES | X41: 70 | Y41: 57 | Z41: =SUM(X41-Y41) | AA41: 0.99450549 | AB41: 1447430 | AC41: 218.5
...

Sheet BD_COMPARATIVA
A1: RUT | B1: RAZON SOCIAL | C1: COD VEN | D1: VENDEDOR | E1: CIUDAD | F1: CANTIDAD T:38 | G1: VALOR T:38 | H1: FACTURADO T:38 | I1: VALOR FACT. T:38
A2: 48787584 | B2: ROBERTO KOBUS PEMSO | C2: 2 | D2: PATRICIO CUEVAS | E2: ANCUD | F2: 505 | G2: 12867950 | H2: 438 | I2: 11150620
A3: 59133659 | B3: ANA MARIA MANFREDI CARRASCO | C3: 6 | D3: HECTOR CAFFIERO VASQUEZ | E3: OVALLE | F3: 118 | G3: 2963820 | H3: 107 | I3: 2688930
A4: 60311234 | B4: FABIOLA BENAVENTE MEZA | C4: 12 | D4: CARLOS CUEVAS | E4: PARRAL | F4: 62 | G4: 1574380 | H4: 55 | I4: 1399450
A5: 60921830 | B5: NORA BARRAZA MILLA | C5: 6 | D5: HECTOR CAFFIERO VASQUEZ | E5: DIEGO DE ALMAGRO | F5: 67 | G5: 1737330 | H5: 60 | I5: 1562400
A6: 63319104 | B6: LUIS SOUMASTRE RAMIREZ | C6: 6 | D6: HECTOR CAFFIERO VASQUEZ | E6: ARICA | F6: 71 | G6: 1821290 | H6: 65 | I6: 1665350
A7: 67999673 | B7: ANA MARIA SALVATIERRA TAPIA | C7: 2 | D7: PATRICIO CUEVAS | E7: CABILDO | F7: 36 | G7: 917640 | H7: 36 | I7: 917640
A8: 70968371 | B8: GLORIA CECILIA OLIVARES TORRES | C8: 6 | D8: HECTOR CAFFIERO VASQUEZ | E8: CHAﾑARAL | F8: 130 | G8: 3367700 | H8: 125 | I8: 3238750
A9: 71650685 | B9: SERGIO HERNAN CERDA ESCOBAR | C9: 2 | D9: PATRICIO CUEVAS | E9: LOS ANGELES | F9: 290 | G9: 7297100 | H9: 138 | I9: 3473620
A10: 72952936 | B10: ANA SAAVEDRA ORTIZ | C10: 12 | D10: CARLOS CUEVAS | E10: CAﾑETE | F10: 104 | G10: 2694960 | H10: 93 | I10: 2418070
A11: 75099215 | B11: NOLBERTO AVILA CORTES | C11: 2 | D11: PATRICIO CUEVAS | E11: CAUQUENES | F11: 166 | G11: 4210340 | H11: 163 | I11: 4135370
A12: 76348294 | B12: CARLOS MELLA ALVARADO | C12: 2 | D12: PATRICIO CUEVAS | E12: 2 | F12: 259 | G12: 6558410 | H12: 221 | I12: 5596790
A13: 81838518 | B13: CLARA VARGAS NATER | C13: 12 | D13: CARLOS CUEVAS | E13: ANGOL | F13: 102 | G13: 2668980 | H13: 58 | I13: 1517420
A14: 86732041 | B14: ROMAN JUAN CASTRO CAYO | C14: 6 | D14: HECTOR CAFFIERO VASQUEZ | E14: ARICA | F14: 41 | G14: 1029590 | H14: 42 | I14: 1057580
A15: 8780898K | B15: PATRICIA HAFON DESMOND | C15: 6 | D15: HECTOR CAFFIERO VASQUEZ | E15: TOCOPILLA | F15: 8 | G15: 207920 | H15: 0 | I15: 0
A16: 92761525 | B16: CARMEN GLORIA GALLARDO VALERIO | C16: 2 | D16: PATRICIO CUEVAS | E16: LA UNION | F16: 121 | G16: 3165790 | H16: 106 | I16: 2771940
A17: 93052528 | B17: SABINA QUISPE PAIRO | C17: 6 | D17: HECTOR CAFFIERO VASQUEZ | E17: ARICA | F17: 553 | G17: 14187470 | H17: 441 | I17: 11312590
A18: 94411564 | B18: ANA MARIA SANCHEZ LUENGO | C18: 12 | D18: CARLOS CUEVAS | E18: PUREN | F18: 90 | G18: 2316100 | H18: 84 | I18: 2154160
A19: 96234422 | B19: MIRNA PACHECO RABANAL | C19: 2 | D19: PATRICIO CUEVAS | E19: CABRERO | F19: 228 | G19: 5836720 | H19: 198 | I19: 5030020
A20: 102705084 | B20: ELIANA VENTURELLI REGLA | C20: 12 | D20: CARLOS CUEVAS | E20: CAPITAN PASTENE | F20: 190 | G20: 4834100 | H20: 121 | I20: 3051790
A21: 105613059 | B21: MARISOL DURAN NAVARRO | C21: 12 | D21: CARLOS CUEVAS | E21: MELIPILLA | F21: 42 | G21: 1112580 | H21: 41 | I21: 1086590
A22: 10879819K | B22: CELIA VASQUEZ BARRERA | C22: 2 | D22: PATRICIO CUEVAS | E22: VILLARICA | F22: 49 | G22: 1240510 | H22: 40 | I22: 1006600
A23: 114079979 | B23: DANITZA OSSES AEDO | C23: 12 | D23: CARLOS CUEVAS | E23: TRAIGUEN | F23: 106 | G23: 2716940 | H23: 95 | I23: 2438050
A24: 115643592 | B24: BELLA FUENTES PINCHEIRA | C24: 13 | D24: RICHARD CUEVAS | E24: LINARES | F24: 623 | G24: 16052770 | H24: 497 | I24: 12767030
A25: 116841290 | B25: HUGO MONTERO FIGUEROA | C25: 2 | D25: PATRICIO CUEVAS | E25: LOS ANGELES | F25: 397 | G25: 10084030 | H25: 380 | I25: 9639200
A26: 120037366 | B26: ARMANDO BARRIA LEGUE | C26: 3 | D26: SERGIO KRAMARENCO | E26: PUERTO NATALES | F26: 70 | G26: 1772300 | H26: 57 | I26: 1447430
A27: 123737024 | B27: ISVELDA MELO ACEVEDO | C27: 2 | D27: PATRICIO CUEVAS | E27: LINARES | F27: 18 | G27: 467820 | H27: 0 | I27: 0
A28: 12838491K | B28: JESSICA ARAYA CEPEDA | C28: 6 | D28: HECTOR CAFFIERO VASQUEZ | E28: ANTOFAGASTA | F28: 4 | G28: 103960 | H28: 4 | I28: 103960
A29: 136381334 | B29: KAREN HUAMAN LOPEZ | C29: 6 | D29: HECTOR CAFFIERO VASQUEZ | E29: ARICA | F29: 11 | G29: 296890 | H29: 11 | I29: 296890
A30: 137440369 | B30: CARLA ALIAGA | C30: 6 | D30: HECTOR CAFFIERO VASQUEZ | E30: VALLENAR | F30: 192 | G30: 4942080 | H30: 163 | I30: 4191370
A31: 138622045 | B31: PAOLA NAVARRO | C31: 6 | D31: HECTOR CAFFIERO VASQUEZ | E31: ARICA | F31: 48 | G31: 1253520 | H31: 22 | I31: 571780
A32: 139701321 | B32: GLORIA GALINDO PEREZ | C32: 3 | D32: SERGIO KRAMARENCO | E32: COYHAIQUE | F32: 250 | G32: 6409500 | H32: 240 | I32: 6159600
A33: 143849244 | B33: MONICA SANDOVAL NAVARRETE | C33: 2 | D33: PATRICIO CUEVAS | E33: COLLIPULLI | F33: 92 | G33: 2329080 | H33: 92 | I33: 2335080
A34: 144052439 | B34: CECILIA RIVERA ROMERO | C34: 2 | D34: PATRICIO CUEVAS | E34: TEMUCO | F34: 366 | G34: 9408340 | H34: 340 | I34: 8732600
A35: 144967860 | B35: CRISTIAN ALEJANDRO FUENTES FLORES | C35: 12 | D35: CARLOS CUEVAS | E35: RANCAGUA | F35: 359 | G35: 9313410 | H35: 228 | I35: 5950720
A36: 146351107 | B36: CAROLINA MIRANDA | C36: 12 | D36: CARLOS CUEVAS | E36: SANTA CRUZ | F36: 304 | G36: 7886960 | H36: 269 | I36: 6956310
A37: 154536493 | B37: MARITZA TOSSO CATRICURA | C37: 3 | D37: SERGIO KRAMARENCO | E37: PANGUIPULLI | F37: 44 | G37: 1111560 | H37: 20 | I37: 511800
A38: 16065905K | B38: PATRICIA CANALES OYARZUN | C38: 3 | D38: SERGIO KRAMARENCO | E38: PUNTA ARENAS | F38: 216 | G38: 5676840 | H38: 125 | I38: 3276750
A39: 162593110 | B39: KATERIN FRANCHESCA CASANGA SANTANA | C39: 6 | D39: HECTOR CAFFIERO VASQUEZ | E39: CALAMA | F39: 214 | G39: 5603860 | H39: 125 | I39: 3258750
A40: 162603744 | B40: JETZABEL AGUIRRE ALVAREZ | C40: 6 | D40: HECTOR CAFFIERO VASQUEZ | E40: CALAMA | F40: 446 | G40: 11605540 | H40: 396 | I40: 10290040
...

Sheet TRAYECTORIA
A1: CLIENTES DE TRAYECTORIA
A3: N° | B3: CLIENTES | C3: DESCUENTO
A4: 1 | B4: COMERCIAL GERMANI | C4: 0.05
A5: 2 | B5: ESTABLECIMIENTO GERMANI | C5: 0.05
A6: 3 | B6: SEIDEMAN | C6: 0.05
A7: 4 | B7: MULTICENTRO | C7: -
A8: 5 | B8: INV JULIAN | C8: 0.05
A9: 6 | B9: JAVER HNOS | C9: 0.05
A10: 7 | B10: COMERCIAL NACE | C10: 0.05
A11: 8 | B11: ALMACENES ELTIT | C11: 0.05
A12: 9 | B12: DOLLY | C12: 0.05
A13: 10 | B13: ROBERTO KOBUS | C13: 0.05

Sheet DESCUENTO COLE 18
A2: DESCUENTO COLE 18 (10/09/2021) POR PAGO DE CONTADO
B4: N° | C4: CLIENTES | D4: DESCUENTO
B5: 1 | C5: SOC.FLORES ALMANDOZ NA | D5: 0.05
B6: 2 | C6: FORCAEL | D6: 0.05
B7: 3 | C7: DOLLY | D7: 0.05
